Workbook
Name MY_FUNCTION1: LAMBDA(IF(COUNTA('5'!$F$2:$F$7)=0,"",AVERAGE('5'!$F$2:$F$7)))

Sheet 5t
A1: Hemayetpur Laboratory School and College
A2: 3rd Tutorial Examination Marksheet-2025
A3: Class: Five
A4: SN | B4: Student’s Name | C4: Subject’s Name & Marks
C5: Bangla | D5: English | E5: Math. | F5: Science | G5: B.G.S | H5: Religion | I5: Total | J5: Rank
A6: 1 | B6: SUBORNA AKTER JUI | C6: 30 | D6: 30 | E6: 21 | F6: 30 | G6: 30 | H6: 30 | I6: =SUM(C6:H6) -> 171 | J6: =RANK(I6,$I$6:$I$21) -> 2
A7: 2 | B7: JANNATUL FERDOUS | C7: 30 | D7: 30 | E7: 20 | F7: 30 | G7: 30 | H7: 30 | I7: =SUM(C7:H7) -> 170 | J7: =RANK(I7,$I$6:$I$21) -> 3
A8: 3 | B8: SHAWRIN KHAN SUROVI | C8: 29 | D8: 30 | E8: 20 | F8: 28 | G8: 30 | H8: 30 | I8: =SUM(C8:H8) -> 167 | J8: =RANK(I8,$I$6:$I$21) -> 6
A9: 4 | B9: SAMIUL HAQUE SAIM | C9: 30 | D9: 30 | E9: 25 | F9: 30 | G9: 30 | H9: 30 | I9: =SUM(C9:H9) -> 175 | J9: =RANK(I9,$I$6:$I$21) -> 1
A10: 5 | B10: BORHAN MIA | C10: 30 | D10: 28 | E10: 20 | F10: 30 | G10: 30 | H10: 30 | I10: =SUM(C10:H10) -> 168 | J10: =RANK(I10,$I$6:$I$21) -> 5
A11: 6 | B11: AZMIRA AKTER DINA | C11: 30 | D11: 28 | E11: 15 | F11: 30 | G11: 27 | H11: 30 | I11: =SUM(C11:H11) -> 160 | J11: =RANK(I11,$I$6:$I$21) -> 9
A12: 7 | B12: SHAMMI AKTER JUI | C12: 30 | D12: 26 | E12: 10 | F12: 30 | G12: 27 | H12: 30 | I12: =SUM(C12:H12) -> 153 | J12: =RANK(I12,$I$6:$I$21) -> 10
A13: 8 | B13: ROJJOB | C13: 30 | D13: 28 | E13: 20 | F13: 30 | G13: 25 | H13: 30 | I13: =SUM(C13:H13) -> 163 | J13: =RANK(I13,$I$6:$I$21) -> 8
A14: 9 | B14: SHIRHUDZZAMAN TAMIM | C14: 30 | D14: 28 | E14: 26 | F14: 30 | G14: 26 | H14: 30 | I14: =SUM(C14:H14) -> 170 | J14: =RANK(I14,$I$6:$I$21) -> 3
A15: 10 | B15: SHABBIR HOSSAN | C15: 10 | D15: 20 | E15: 15 | F15: 10 | G15: 24 | H15: 30 | I15: =SUM(C15:H15) -> 109 | J15: =RANK(I15,$I$6:$I$21) -> 16
A16: 11 | B16: FIROJ BABU | C16: 30 | D16: 24 | E16: 10 | F16: 30 | G16: 25 | H16: 30 | I16: =SUM(C16:H16) -> 149 | J16: =RANK(I16,$I$6:$I$21) -> 11
A17: 12 | B17: SAFAYET HOSSEN | C17: 22 | D17: 26 | E17: 11 | F17: 22 | G17: 25 | H17: 30 | I17: =SUM(C17:H17) -> 136 | J17: =RANK(I17,$I$6:$I$21) -> 13
... A21: 16 | B21: MOSADDIK BILLAH FAHAD | C21: 27 | D21: 20 | E21: 10 | F21: 20 | G21: 20 | H21: 25 | I21: =SUM(C21:H21) -> 122 | J21: =RANK(I21,$I$6:$I$21) -> 14

Sheet 5s
A1: Hemayetpur Laboratory School and College
A2: Annual Examination Marksheet-2025
A3: Class: Five
A4: SN | B4: Student’s Name | C4: Subject’s Name & Marks
C5: Bangla | D5: English | E5: Math. | F5: Science | G5: B.G.S | H5: Religion | I5: Total | J5: Rank
A6: 1 | B6: SUBORNA AKTER JUI | C6: 69 | D6: 70 | E6: 61 | F6: 65 | G6: 65 | H6: 70 | I6: =SUM(C6:H6) -> 400 | J6: =RANK(I6,$I$6:$I$21) -> 1 | L6: 171 | M6: 400 | N6: =SUM(L6:M6) -> 571
A7: 2 | B7: JANNATUL FERDOUS | C7: 66 | D7: 70 | E7: 61 | F7: 66 | G7: 65 | H7: 70 | I7: =SUM(C7:H7) -> 398 | J7: =RANK(I7,$I$6:$I$21) -> 2 | L7: 170 | M7: 398 | N7: =SUM(L7:M7) -> 568
A8: 3 | B8: SHAWRIN KHAN SUROVI | C8: 64 | D8: 50 | E8: 60 | F8: 59 | G8: 60 | H8: 69 | I8: =SUM(C8:H8) -> 362 | J8: =RANK(I8,$I$6:$I$21) -> 5 | L8: 167 | M8: 362 | N8: =SUM(L8:M8) -> 529
A9: 4 | B9: SAMIUL HAQUE SAIM | C9: 69 | D9: 60 | E9: 62 | F9: 67 | G9: 64 | H9: 67 | I9: =SUM(C9:H9) -> 389 | J9: =RANK(I9,$I$6:$I$21) -> 3 | L9: 175 | M9: 389 | N9: =SUM(L9:M9) -> 564
A10: 5 | B10: BORHAN MIA | C10: 63 | D10: 65 | E10: 62 | F10: 67 | G10: 58 | H10: 70 | I10: =SUM(C10:H10) -> 385 | J10: =RANK(I10,$I$6:$I$21) -> 4 | L10: 168 | M10: 385 | N10: =SUM(L10:M10) -> 553
A11: 6 | B11: AZMIRA AKTER DINA | C11: 54 | D11: 33 | E11: 45 | F11: 47 | G11: 45 | H11: 67 | I11: =SUM(C11:H11) -> 291 | J11: =RANK(I11,$I$6:$I$21) -> 7
A12: 7 | B12: SHAMMI AKTER JUI | C12: 52 | D12: 35 | E12: 33 | F12: 36 | G12: 51 | H12: 68 | I12: =SUM(C12:H12) -> 275 | J12: =RANK(I12,$I$6:$I$21) -> 8
A13: 8 | B13: ROJJOB | C13: 59 | D13: 25 | E13: 40 | F13: 50 | G13: 35 | H13: 45 | I13: =SUM(C13:H13) -> 254 | J13: =RANK(I13,$I$6:$I$21) -> 10
A14: 9 | B14: SHIRHUDZZAMAN TAMIM | C14: 61 | D14: 40 | E14: 44 | F14: 53 | G14: 50 | H14: 68 | I14: =SUM(C14:H14) -> 316 | J14: =RANK(I14,$I$6:$I$21) -> 6
A15: 10 | B15: SHABBIR HOSSAN | C15: 45 | D15: 30 | E15: 25 | F15: 25 | G15: 38 | H15: 40 | I15: =SUM(C15:H15) -> 203 | J15: =RANK(I15,$I$6:$I$21) -> 14
A16: 11 | B16: FIROJ BABU | C16: 58 | D16: 35 | E16: 40 | F16: 30 | G16: 28 | H16: 41 | I16: =SUM(C16:H16) -> 232 | J16: =RANK(I16,$I$6:$I$21) -> 11
A17: 12 | B17: SAFAYET HOSSEN | C17: 46 | D17: 25 | E17: 40 | F17: 29 | G17: 26 | H17: 62 | I17: =SUM(C17:H17) -> 228 | J17: =RANK(I17,$I$6:$I$21) -> 12
A18: 13 | B18: RIFAT HOSSEN | C18: 49 | D18: 33 | E18: 25 | F18: 38 | G18: 25 | H18: 58 | I18: =SUM(C18:H18) -> 228 | J18: =RANK(I18,$I$6:$I$21) -> 12
A19: 14 | B19: SHAWON | C19: 48 | D19: 33 | E19: 58 | F19: 51 | G19: 28 | H19: 57 | I19: =SUM(C19:H19) -> 275 | J19: =RANK(I19,$I$6:$I$21) -> 8
A20: 15 | B20: NUSRAT MAHI | C20: 40 | D20: 25 | E20: 25 | F20: 24 | G20: 24 | H20: 32 | I20: =SUM(C20:H20) -> 170 | J20: =RANK(I20,$I$6:$I$21) -> 15
A21: 16 | B21: MOSADDIK BILLAH FAHAD | I21: =SUM(C21:H21) -> 0 | J21: =RANK(I21,$I$6:$I$21) -> 16
C23: 400 | D23: 385 | E23: 389 | F23: 385
C24: 171 | D24: 170 | E24: 175 | F24: 168
C25: =SUM(C23:C24) -> 571 | D25: =SUM(D23:D24) -> 555 | E25: =SUM(E23:E24) -> 564 | F25: =SUM(F23:F24) -> 553

Sheet 5
A1: SN | B1: Student’s Name | C1: ='5s'!B6 -> SUBORNA AKTER JUI
A2: 1 | B2: Subject’s Name | C2: 3rd Tutorial Exam (30) | D2: 3rd Semester Exam (70) | E2: Total Marks | F2: Grade Letter | G2: Grade Point | H2: G.P.A
B3: Bangla | C3: ='5t'!C6 -> 30 | D3: ='5s'!C6 -> 69 | E3: =SUM(C3:D3) -> 99 | F3: =IF(E3>=80,"A+", IF(E3>=70,"A", IF(E3>=60,"A-", IF(E3>=50,"B", IF(E3>=40,"C", IF(E3>=33,"D","F")))))) -> A+ | G3: =IF(E3>=80,5, IF(E3>=70,4, IF(E3>=60,3.5, IF(E3>=50,3, IF(E3>=40,2, IF(E3>=33,1,0)))))) -> 5 | H3: =AVERAGE( VALUE(G3), VALUE(G4), VALUE(G5), VALUE(G6), VALUE(G7), VALUE(G8)) -> 5
B4: English | C4: ='5t'!D7 -> 30 | D4: ='5s'!D6 -> 70 | E4: =SUM(C4:D4) -> 100 | F4: =IF(E4>=80,"A+", IF(E4>=70,"A", IF(E4>=60,"A-", IF(E4>=50,"B", IF(E4>=40,"C", IF(E4>=33,"D","F")))))) -> A+ | G4: =IF(E4>=80,5, IF(E4>=70,4, IF(E4>=60,3.5, IF(E4>=50,3, IF(E4>=40,2, IF(E4>=33,1,0)))))) -> 5
B5: Mathematics | C5: ='5t'!E6 -> 21 | D5: ='5s'!E6 -> 61 | E5: =SUM(C5:D5) -> 82 | F5: =IF(E5>=80,"A+", IF(E5>=70,"A", IF(E5>=60,"A-", IF(E5>=50,"B", IF(E5>=40,"C", IF(E5>=33,"D","F")))))) -> A+ | G5: =IF(E5>=80,5, IF(E5>=70,4, IF(E5>=60,3.5, IF(E5>=50,3, IF(E5>=40,2, IF(E5>=33,1,0)))))) -> 5
B6: Science | C6: ='5t'!F6 -> 30 | D6: ='5s'!F6 -> 65 | E6: =SUM(C6:D6) -> 95 | F6: =IF(E6>=80,"A+", IF(E6>=70,"A", IF(E6>=60,"A-", IF(E6>=50,"B", IF(E6>=40,"C", IF(E6>=33,"D","F")))))) -> A+ | G6: =IF(E6>=80,5, IF(E6>=70,4, IF(E6>=60,3.5, IF(E6>=50,3, IF(E6>=40,2, IF(E6>=33,1,0)))))) -> 5
B7: B.G.S | C7: ='5t'!G6 -> 30 | D7: ='5s'!G6 -> 65 | E7: =SUM(C7:D7) -> 95 | F7: =IF(E7>=80,"A+", IF(E7>=70,"A", IF(E7>=60,"A-", IF(E7>=50,"B", IF(E7>=40,"C", IF(E7>=33,"D","F")))))) -> A+ | G7: =IF(E7>=80,5, IF(E7>=70,4, IF(E7>=60,3.5, IF(E7>=50,3, IF(E7>=40,2, IF(E7>=33,1,0)))))) -> 5
B8: Religion | C8: ='5t'!H6 -> 30 | D8: ='5s'!H6 -> 70 | E8: =SUM(C8:D8) -> 100 | F8: =IF(E8>=80,"A+", IF(E8>=70,"A", IF(E8>=60,"A-", IF(E8>=50,"B", IF(E8>=40,"C", IF(E8>=33,"D","F")))))) -> A+ | G8: =IF(E8>=80,5, IF(E8>=70,4, IF(E8>=60,3.5, IF(E8>=50,3, IF(E8>=40,2, IF(E8>=33,1,0)))))) -> 5
A9: SN | B9: Student’s Name | C9: ='5s'!B7 -> JANNATUL FERDOUS
A10: 2 | B10: Subject’s Name | C10: ='5'!C2 -> 3rd Tutorial Exam (30) | D10: ='5'!D2 -> 3rd Semester Exam (70) | E10: Total Marks | F10: Grade Letter | G10: Grade Point | H10: G.P.A
B11: Bangla | C11: ='5t'!C7 -> 30 | D11: ='5s'!C7 -> 66 | E11: =SUM(C11:D11) -> 96 | F11: =IF(E11>=80,"A+", IF(E11>=70,"A", IF(E11>=60,"A-", IF(E11>=50,"B", IF(E11>=40,"C", IF(E11>=33,"D","F")))))) -> A+ | G11: =IF(E11>=80,5, IF(E11>=70,4, IF(E11>=60,3.5, IF(E11>=50,3, IF(E11>=40,2, IF(E11>=33,1,0)))))) -> 5 | H11: =AVERAGE( VALUE(G11), VALUE(G12), VALUE(G13), VALUE(G14), VALUE(G15), VALUE(G16)) -> 5
B12: English | C12: ='5t'!D7 -> 30 | D12: ='5s'!D7 -> 70 | E12: =SUM(C12:D12) -> 100 | F12: =IF(E12>=80,"A+", IF(E12>=70,"A", IF(E12>=60,"A-", IF(E12>=50,"B", IF(E12>=40,"C", IF(E12>=33,"D","F")))))) -> A+ | G12: =IF(E12>=80,5, IF(E12>=70,4, IF(E12>=60,3.5, IF(E12>=50,3, IF(E12>=40,2, IF(E12>=33,1,0)))))) -> 5
B13: Mathematics | C13: ='5t'!E7 -> 20 | D13: ='5s'!E7 -> 61 | E13: =SUM(C13:D13) -> 81 | F13: =IF(E13>=80,"A+", IF(E13>=70,"A", IF(E13>=60,"A-", IF(E13>=50,"B", IF(E13>=40,"C", IF(E13>=33,"D","F")))))) -> A+ | G13: =IF(E13>=80,5, IF(E13>=70,4, IF(E13>=60,3.5, IF(E13>=50,3, IF(E13>=40,2, IF(E13>=33,1,0)))))) -> 5
B14: Science | C14: ='5t'!F7 -> 30 | D14: ='5s'!F7 -> 66 | E14: =SUM(C14:D14) -> 96 | F14: =IF(E14>=80,"A+", IF(E14>=70,"A", IF(E14>=60,"A-", IF(E14>=50,"B", IF(E14>=40,"C", IF(E14>=33,"D","F")))))) -> A+ | G14: =IF(E14>=80,5, IF(E14>=70,4, IF(E14>=60,3.5, IF(E14>=50,3, IF(E14>=40,2, IF(E14>=33,1,0)))))) -> 5
B15: B.G.S | C15: ='5t'!G7 -> 30 | D15: ='5s'!G7 -> 65 | E15: =SUM(C15:D15) -> 95 | F15: =IF(E15>=80,"A+", IF(E15>=70,"A", IF(E15>=60,"A-", IF(E15>=50,"B", IF(E15>=40,"C", IF(E15>=33,"D","F")))))) -> A+ | G15: =IF(E15>=80,5, IF(E15>=70,4, IF(E15>=60,3.5, IF(E15>=50,3, IF(E15>=40,2, IF(E15>=33,1,0)))))) -> 5
B16: Religion | C16: ='5t'!H7 -> 30 | D16: ='5s'!H7 -> 70 | E16: =SUM(C16:D16) -> 100 | F16: =IF(E16>=80,"A+", IF(E16>=70,"A", IF(E16>=60,"A-", IF(E16>=50,"B", IF(E16>=40,"C", IF(E16>=33,"D","F")))))) -> A+ | G16: =IF(E16>=80,5, IF(E16>=70,4, IF(E16>=60,3.5, IF(E16>=50,3, IF(E16>=40,2, IF(E16>=33,1,0)))))) -> 5
A17: SN | B17: Student’s Name | C17: ='5s'!B8 -> SHAWRIN KHAN SUROVI
A18: 3 | B18: Subject’s Name | C18: ='5'!C2 -> 3rd Tutorial Exam (30) | D18: ='5'!D2 -> 3rd Semester Exam (70) | E18: Total Marks | F18: Grade Letter | G18: Grade Point | H18: G.P.A
B19: Bangla | C19: ='5t'!C8 -> 29 | D19: ='5s'!C8 -> 64 | E19: =SUM(C19:D19) -> 93 | F19: =IF(E19>=80,"A+", IF(E19>=70,"A", IF(E19>=60,"A-", IF(E19>=50,"B", IF(E19>=40,"C", IF(E19>=33,"D","F")))))) -> A+ | G19: =IF(E19>=80,5, IF(E19>=70,4, IF(E19>=60,3.5, IF(E19>=50,3, IF(E19>=40,2, IF(E19>=33,1,0)))))) -> 5 | H19: =AVERAGE( VALUE(G19), VALUE(G20), VALUE(G21), VALUE(G22), VALUE(G23), VALUE(G24)) -> 5
B20: English | C20: ='5t'!D8 -> 30 | D20: ='5s'!D8 -> 50 | E20: =SUM(C20:D20) -> 80 | F20: =IF(E20>=80,"A+", IF(E20>=70,"A", IF(E20>=60,"A-", IF(E20>=50,"B", IF(E20>=40,"C", IF(E20>=33,"D","F")))))) -> A+ | G20: =IF(E20>=80,5, IF(E20>=70,4, IF(E20>=60,3.5, IF(E20>=50,3, IF(E20>=40,2, IF(E20>=33,1,0)))))) -> 5
B21: Mathematics | C21: ='5t'!E8 -> 20 | D21: ='5s'!E8 -> 60 | E21: =SUM(C21:D21) -> 80 | F21: =IF(E21>=80,"A+", IF(E21>=70,"A", IF(E21>=60,"A-", IF(E21>=50,"B", IF(E21>=40,"C", IF(E21>=33,"D","F")))))) -> A+ | G21: =IF(E21>=80,5, IF(E21>=70,4, IF(E21>=60,3.5, IF(E21>=50,3, IF(E21>=40,2, IF(E21>=33,1,0)))))) -> 5
B22: Science | C22: ='5t'!F8 -> 28 | D22: ='5s'!F8 -> 59 | E22: =SUM(C22:D22) -> 87 | F22: =IF(E22>=80,"A+", IF(E22>=70,"A", IF(E22>=60,"A-", IF(E22>=50,"B", IF(E22>=40,"C", IF(E22>=33,"D","F")))))) -> A+ | G22: =IF(E22>=80,5, IF(E22>=70,4, IF(E22>=60,3.5, IF(E22>=50,3, IF(E22>=40,2, IF(E22>=33,1,0)))))) -> 5
B23: B.G.S | C23: ='5t'!G8 -> 30 | D23: ='5s'!G8 -> 60 | E23: =SUM(C23:D23) -> 90 | F23: =IF(E23>=80,"A+", IF(E23>=70,"A", IF(E23>=60,"A-", IF(E23>=50,"B", IF(E23>=40,"C", IF(E23>=33,"D","F")))))) -> A+ | G23: =IF(E23>=80,5, IF(E23>=70,4, IF(E23>=60,3.5, IF(E23>=50,3, IF(E23>=40,2, IF(E23>=33,1,0)))))) -> 5
B24: Religion | C24: ='5t'!H8 -> 30 | D24: ='5s'!H8 -> 69 | E24: =SUM(C24:D24) -> 99 | F24: =IF(E24>=80,"A+", IF(E24>=70,"A", IF(E24>=60,"A-", IF(E24>=50,"B", IF(E24>=40,"C", IF(E24>=33,"D","F")))))) -> A+ | G24: =IF(E24>=80,5, IF(E24>=70,4, IF(E24>=60,3.5, IF(E24>=50,3, IF(E24>=40,2, IF(E24>=33,1,0)))))) -> 5
A25: SN | B25: Student’s Name | C25: ='5s'!B9 -> SAMIUL HAQUE SAIM
A26: 4 | B26: Subject’s Name | C26: ='5'!C2 -> 3rd Tutorial Exam (30) | D26: ='5'!D2 -> 3rd Semester Exam (70) | E26: Total Marks | F26: Grade Letter | G26: Grade Point | H26: G.P.A
B27: Bangla | C27: ='5t'!C9 -> 30 | D27: ='5s'!C9 -> 69 | E27: =SUM(C27:D27) -> 99 | F27: =IF(E27>=80,"A+", IF(E27>=70,"A", IF(E27>=60,"A-", IF(E27>=50,"B", IF(E27>=40,"C", IF(E27>=33,"D","F")))))) -> A+ | G27: =IF(E27>=80,5, IF(E27>=70,4, IF(E27>=60,3.5, IF(E27>=50,3, IF(E27>=40,2, IF(E27>=33,1,0)))))) -> 5 | H27: =AVERAGE( VALUE(G27), VALUE(G28), VALUE(G29), VALUE(G30), VALUE(G31), VALUE(G32)) -> 5
B28: English | C28: ='5t'!D9 -> 30 | D28: ='5s'!D9 -> 60 | E28: =SUM(C28:D28) -> 90 | F28: =IF(E28>=80,"A+", IF(E28>=70,"A", IF(E28>=60,"A-", IF(E28>=50,"B", IF(E28>=40,"C", IF(E28>=33,"D","F")))))) -> A+ | G28: =IF(E28>=80,5, IF(E28>=70,4, IF(E28>=60,3.5, IF(E28>=50,3, IF(E28>=40,2, IF(E28>=33,1,0)))))) -> 5
B29: Mathematics | C29: ='5t'!E9 -> 25 | D29: ='5s'!E9 -> 62 | E29: =SUM(C29:D29) -> 87 | F29: =IF(E29>=80,"A+", IF(E29>=70,"A", IF(E29>=60,"A-", IF(E29>=50,"B", IF(E29>=40,"C", IF(E29>=33,"D","F")))))) -> A+ | G29: =IF(E29>=80,5, IF(E29>=70,4, IF(E29>=60,3.5, IF(E29>=50,3, IF(E29>=40,2, IF(E29>=33,1,0)))))) -> 5
B30: Science | C30: ='5t'!F9 -> 30 | D30: ='5s'!F9 -> 67 | E30: =SUM(C30:D30) -> 97 | F30: =IF(E30>=80,"A+", IF(E30>=70,"A", IF(E30>=60,"A-", IF(E30>=50,"B", IF(E30>=40,"C", IF(E30>=33,"D","F")))))) -> A+ | G30: =IF(E30>=80,5, IF(E30>=70,4, IF(E30>=60,3.5, IF(E30>=50,3, IF(E30>=40,2, IF(E30>=33,1,0)))))) -> 5
B31: B.G.S | C31: ='5t'!G9 -> 30 | D31: ='5s'!G9 -> 64 | E31: =SUM(C31:D31) -> 94 | F31: =IF(E31>=80,"A+", IF(E31>=70,"A", IF(E31>=60,"A-", IF(E31>=50,"B", IF(E31>=40,"C", IF(E31>=33,"D","F")))))) -> A+ | G31: =IF(E31>=80,5, IF(E31>=70,4, IF(E31>=60,3.5, IF(E31>=50,3, IF(E31>=40,2, IF(E31>=33,1,0)))))) -> 5
B32: Religion | C32: ='5t'!H9 -> 30 | D32: ='5s'!H9 -> 67 | E32: =SUM(C32:D32) -> 97 | F32: =IF(E32>=80,"A+", IF(E32>=70,"A", IF(E32>=60,"A-", IF(E32>=50,"B", IF(E32>=40,"C", IF(E32>=33,"D","F")))))) -> A+ | G32: =IF(E32>=80,5, IF(E32>=70,4, IF(E32>=60,3.5, IF(E32>=50,3, IF(E32>=40,2, IF(E32>=33,1,0)))))) -> 5
A33: SN | B33: Student’s Name | C33: ='5s'!B10 -> BORHAN MIA
A34: 5 | B34: Subject’s Name | C34: ='5'!C2 -> 3rd Tutorial Exam (30) | D34: ='5'!D2 -> 3rd Semester Exam (70) | E34: Total Marks | F34: Grade Letter | G34: Grade Point | H34: G.P.A
B35: Bangla | C35: ='5t'!C10 -> 30 | D35: ='5s'!C10 -> 63 | E35: =SUM(C35:D35) -> 93 | F35: =IF(E35>=80,"A+", IF(E35>=70,"A", IF(E35>=60,"A-", IF(E35>=50,"B", IF(E35>=40,"C", IF(E35>=33,"D","F")))))) -> A+ | G35: =IF(E35>=80,5, IF(E35>=70,4, IF(E35>=60,3.5, IF(E35>=50,3, IF(E35>=40,2, IF(E35>=33,1,0)))))) -> 5 | H35: =AVERAGE( VALUE(G35), VALUE(G36), VALUE(G37), VALUE(G38), VALUE(G39), VALUE(G40)) -> 5
B36: English | C36: ='5t'!D10 -> 28 | D36: ='5s'!D10 -> 65 | E36: =SUM(C36:D36) -> 93 | F36: =IF(E36>=80,"A+", IF(E36>=70,"A", IF(E36>=60,"A-", IF(E36>=50,"B", IF(E36>=40,"C", IF(E36>=33,"D","F")))))) -> A+ | G36: =IF(E36>=80,5, IF(E36>=70,4, IF(E36>=60,3.5, IF(E36>=50,3, IF(E36>=40,2, IF(E36>=33,1,0)))))) -> 5
B37: Mathematics | C37: ='5t'!E10 -> 20 | D37: ='5s'!E10 -> 62 | E37: =SUM(C37:D37) -> 82 | F37: =IF(E37>=80,"A+", IF(E37>=70,"A", IF(E37>=60,"A-", IF(E37>=50,"B", IF(E37>=40,"C", IF(E37>=33,"D","F")))))) -> A+ | G37: =IF(E37>=80,5, IF(E37>=70,4, IF(E37>=60,3.5, IF(E37>=50,3, IF(E37>=40,2, IF(E37>=33,1,0)))))) -> 5
B38: Science | C38: ='5t'!F10 -> 30 | D38: ='5s'!F10 -> 67 | E38: =SUM(C38:D38) -> 97 | F38: =IF(E38>=80,"A+", IF(E38>=70,"A", IF(E38>=60,"A-", IF(E38>=50,"B", IF(E38>=40,"C", IF(E38>=33,"D","F")))))) -> A+ | G38: =IF(E38>=80,5, IF(E38>=70,4, IF(E38>=60,3.5, IF(E38>=50,3, IF(E38>=40,2, IF(E38>=33,1,0)))))) -> 5
B39: B.G.S | C39: ='5t'!G10 -> 30 | D39: ='5s'!G10 -> 58 | E39: =SUM(C39:D39) -> 88 | F39: =IF(E39>=80,"A+", IF(E39>=70,"A", IF(E39>=60,"A-", IF(E39>=50,"B", IF(E39>=40,"C", IF(E39>=33,"D","F")))))) -> A+ | G39: =IF(E39>=80,5, IF(E39>=70,4, IF(E39>=60,3.5, IF(E39>=50,3, IF(E39>=40,2, IF(E39>=33,1,0)))))) -> 5
B40: Religion | C40: ='5t'!H10 -> 30 | D40: ='5s'!H10 -> 70 | E40: =SUM(C40:D40) -> 100 | F40: =IF(E40>=80,"A+", IF(E40>=70,"A", IF(E40>=60,"A-", IF(E40>=50,"B", IF(E40>=40,"C", IF(E40>=33,"D","F")))))) -> A+ | G40: =IF(E40>=80,5, IF(E40>=70,4, IF(E40>=60,3.5, IF(E40>=50,3, IF(E40>=40,2, IF(E40>=33,1,0)))))) -> 5
...

Sheet 5r
A1: Hemayetpur Laboratory School and College
A2: Annual Examination Results-2025
A3: Class: Five
A4: SN | B4: Student’s Name | C4: Rank
C5: G.P.A | D5: Rank
A6: 1 | B6: SUBORNA AKTER JUI | C6: ='5'!H3 -> 5 | D6: =RANK(C6,$C$6:$C$21) -> 1
A7: 2 | B7: JANNATUL FERDOUS | C7: ='5'!H11 -> 5 | D7: =RANK(C7,$C$6:$C$21) -> 1
A8: 3 | B8: SHAWRIN KHAN SUROVI | C8: ='5'!H19 -> 5 | D8: =RANK(C8,$C$6:$C$21) -> 1
A9: 4 | B9: SAMIUL HAQUE SAIM | C9: ='5'!H27 -> 5 | D9: =RANK(C9,$C$6:$C$21) -> 1
A10: 5 | B10: BORHAN MIA | C10: ='5'!H35 -> 5 | D10: =RANK(C10,$C$6:$C$21) -> 1
A11: 6 | B11: AZMIRA AKTER DINA | C11: ='5'!H43 -> 4.1666667 | D11: =RANK(C11,$C$6:$C$21) -> 7
A12: 7 | B12: SHAMMI AKTER JUI | C12: ='5'!H51 -> 3.8333333 | D12: =RANK(C12,$C$6:$C$21) -> 10
A13: 8 | B13: ROJJOB | C13: ='5'!H59 -> 4 | D13: =RANK(C13,$C$6:$C$21) -> 9
A14: 9 | B14: SHIRHUDZZAMAN TAMIM | C14: ='5'!H67 -> 4.4166667 | D14: =RANK(C14,$C$6:$C$21) -> 6
A15: 10 | B15: SHABBIR HOSSAN | C15: ='5'!H75 -> 2.75 | D15: =RANK(C15,$C$6:$C$21) -> 14
A16: 11 | B16: FIROJ BABU | C16: ='5'!H83 -> 3.5833333 | D16: =RANK(C16,$C$6:$C$21) -> 11
A17: 12 | B17: SAFAYET HOSSEN | C17: ='5'!H91 -> 3.4166667 | D17: =RANK(C17,$C$6:$C$21) -> 12
A18: 13 | B18: RIFAT HOSSEN | C18: ='5'!H99 -> 3.25 | D18: =RANK(C18,$C$6:$C$21) -> 13
A19: 14 | B19: SHAWON | C19: ='5'!H107 -> 4.0833333 | D19: =RANK(C19,$C$6:$C$21) -> 8
A20: 15 | B20: NUSRAT MAHI | C20: ='5'!H115 -> 2.0833333 | D20: =RANK(C20,$C$6:$C$21) -> 15
A21: 16 | B21: MOSADDIK BILLAH FAHAD | C21: ='5'!H123 -> 0 | D21: =RANK(C21,$C$6:$C$21) -> 16

Sheet 6t
A1: Hemayetpur Laboratory School and College
A2: 3rd Tutorial Examination Marksheet-2025
A3: Class: Six
A4: SN | B4: Student’s Name | C4: Subject’s Name & Marks
C5: Bangla-1 | D5: Bangla-2 | E5: English -1 | F5: English -2 | G5: Math. | H5: Science | I5: B.G.S | J5: Agri. | K5: Religion | L5: ICT | M5: Total | N5: Rank
A6: 1 | B6: RIYA MONI | C6: 25 | E6: 19 | G6: 24 | H6: 30 | I6: 23 | J6: 26 | K6: 30 | L6: 13 | M6: =SUM(C6:L6) -> 190 | N6: =RANK(M6,$M$6:$M$12) -> 1
A7: 2 | B7: JENIYA AKTER | C7: 20 | E7: 13 | G7: 18 | H7: 26 | I7: 19 | J7: 24 | K7: 26 | L7: 12 | M7: =SUM(C7:K7) -> 146 | N7: =RANK(M7,$M$6:$M$12) -> 2
A8: 3 | B8: FATEMA AKTER | C8: 10 | E8: 10 | H8: 10 | J8: 22 | K8: 16 | L8: 8 | M8: =SUM(C8:L8) -> 76 | N8: =RANK(M8,$M$6:$M$12) -> 3
A9: 4 | B9: USAMA | C9: 10 | E9: 10 | G9: 10 | H9: 10 | I9: 10 | J9: 15 | K9: 10 | L9: 8 | M9: =SUM(C9:K9) -> 75 | N9: =RANK(M9,$M$6:$M$12) -> 4
A10: 5 | B10: SHAHABIR | C10: 10 | E10: 10 | G10: 10 | H10: 10 | I10: 10 | K10: 10 | L10: 9 | M10: =SUM(C10:K10) -> 60 | N10: =RANK(M10,$M$6:$M$12) -> 5
A11: 6 | B11: MIM AKTER SHATHI | E11: 10 | I11: 10 | K11: 10 | L11: 8 | M11: =SUM(C11:K11) -> 30 | N11: =RANK(M11,$M$6:$M$12) -> 6
A12: 7 | B12: ETI PRIYA | E12: 10 | I12: 10 | K12: 10 | L12: 8 | M12: =SUM(C12:K12) -> 30 | N12: =RANK(M12,$M$6:$M$12) -> 6

Sheet 6s
A1: Hemayetpur Laboratory School and College
A2: Annual Examination Marksheet-2025
A3: Class: Six
A4: SN | B4: Student’s Name | C4: Subject’s Name & Marks
C5: Bangla-1 | D5: Bangla-2 | E5: English -1 | F5: English -2 | G5: Math. | H5: Science | I5: B.G.S | J5: Agri. | K5: Religion | L5: ICT | M5: Total | N5: Rank
A6: 1 | B6: RIYA MONI | C6: 55 | D6: 45 | E6: 64 | F6: 48 | G6: 55 | H6: 54 | I6: 63 | J6: 50 | K6: 70 | L6: 13 | M6: =SUM(C6:L6) -> 517 | N6: =RANK(M6,$M$6:$M$12) -> 1
A7: 2 | B7: JENIYA AKTER | C7: 32 | D7: 44 | E7: 40 | F7: 25 | G7: 34 | H7: 38 | I7: 53 | J7: 26 | K7: 62 | L7: 12 | M7: =SUM(C7:L7) -> 366 | N7: =RANK(M7,$M$6:$M$12) -> 2
A8: 3 | B8: FATEMA AKTER | C8: 25 | D8: 16 | E8: 25 | F8: 25 | H8: 33 | I8: 40 | J8: 25 | K8: 26 | M8: =SUM(C8:L8) -> 215 | N8: =RANK(M8,$M$6:$M$12) -> 5
A9: 4 | B9: USAMA | C9: 24 | D9: 16 | E9: 20 | F9: 20 | G9: 24 | H9: 24 | I9: 33 | J9: 24 | K9: 47 | L9: 8 | M9: =SUM(C9:L9) -> 240 | N9: =RANK(M9,$M$6:$M$12) -> 3
A10: 5 | B10: SHAHABIR | C10: 24 | D10: 16 | E10: 25 | F10: 22 | G10: 24 | H10: 26 | I10: 30 | J10: 24 | K10: 29 | L10: 9 | M10: =SUM(C10:L10) -> 229 | N10: =RANK(M10,$M$6:$M$12) -> 4
A11: 6 | B11: MIM AKTER SHATHI | C11: 24 | D11: 16 | K11: 25 | L11: 8 | M11: =SUM(C11:L11) -> 73 | N11: =RANK(M11,$M$6:$M$12) -> 7
A12: 7 | B12: ETI PRIYA | D12: 16 | E12: 24 | F12: 20 | G12: 24 | I12: 25 | J12: 24 | L12: 8 | M12: =SUM(C12:L12) -> 141 | N12: =RANK(M12,$M$6:$M$12) -> 6

Sheet 6
A1: SN | B1: Student’s Name | C1: ='6s'!B6 -> RIYA MONI
A2: 1 | B2: Subject’s Name | C2: 3rd Tutorial Exam (30) | D2: 3rd Semester Exam (70) | E2: Total Marks | F2: Grade Letter | G2: Grade Point | H2: G.P.A
B3: Bangla-1 | C3: ='6t'!C6 -> 25 | D3: ='6s'!C6 -> 55 | E3: =SUM(C3:D3) -> 80 | F3: =IF(E3>=80,"A+", IF(E3>=70,"A", IF(E3>=60,"A-", IF(E3>=50,"B", IF(E3>=40,"C", IF(E3>=33,"D","F")))))) -> A+ | G3: =IF(E3>=80,5, IF(E3>=70,4, IF(E3>=60,3.5, IF(E3>=50,3, IF(E3>=40,2, IF(E3>=33,1,0)))))) -> 5 | H3: =AVERAGE( VALUE(G3), VALUE(G4), VALUE(G5), VALUE(G6), VALUE(G7), VALUE(G8), VALUE(G9), VALUE(G10), VALUE(G11), VALUE(G12)) -> 4.6
B4: Bangla-2 | C4: ='6t'!D6 | D4: ='6s'!D6 -> 45 | E4: =SUM(C4:D4) -> 45 | F4: =IF(E4>=40,"A+", IF(E4>=35,"A", IF(E4>=30,"A-", IF(E4>=25,"B", IF(E4>=20,"C", IF(E4>=16,"D","F")))))) -> A+ | G4: =IF(E4>=40,5, IF(E4>=35,4, IF(E4>=30,3.5, IF(E4>=25,3, IF(E4>=20,2, IF(E4>=16,1,0)))))) -> 5
B5: English-1 | C5: ='6t'!E6 -> 19 | D5: ='6s'!E6 -> 64 | E5: =SUM(C5:D5) -> 83 | F5: =IF(E5>=80,"A+", IF(E5>=70,"A", IF(E5>=60,"A-", IF(E5>=50,"B", IF(E5>=40,"C", IF(E5>=33,"D","F")))))) -> A+ | G5: =IF(E5>=80,5, IF(E5>=70,4, IF(E5>=60,3.5, IF(E5>=50,3, IF(E5>=40,2, IF(E5>=33,1,0)))))) -> 5
B6: English-2 | C6: ='6t'!F6 | D6: ='6s'!F6 -> 48 | E6: =SUM(C6:D6) -> 48 | F6: =IF(E6>=40,"A+", IF(E6>=35,"A", IF(E6>=30,"A-", IF(E6>=25,"B", IF(E6>=20,"C", IF(E6>=16,"D","F")))))) -> A+ | G6: =IF(E6>=40,5, IF(E6>=35,4, IF(E6>=30,3.5, IF(E6>=25,3, IF(E6>=20,2, IF(E6>=16,1,0)))))) -> 5
B7: Mathematics | C7: ='6t'!G6 -> 24 | D7: ='6s'!G6 -> 55 | E7: =SUM(C7:D7) -> 79 | F7: =IF(E7>=80,"A+", IF(E7>=70,"A", IF(E7>=60,"A-", IF(E7>=50,"B", IF(E7>=40,"C", IF(E7>=33,"D","F")))))) -> A | G7: =IF(E7>=80,5, IF(E7>=70,4, IF(E7>=60,3.5, IF(E7>=50,3, IF(E7>=40,2, IF(E7>=33,1,0)))))) -> 4
B8: Science | C8: ='6t'!H6 -> 30 | D8: ='6s'!H6 -> 54 | E8: =SUM(C8:D8) -> 84 | F8: =IF(E8>=80,"A+", IF(E8>=70,"A", IF(E8>=60,"A-", IF(E8>=50,"B", IF(E8>=40,"C", IF(E8>=33,"D","F")))))) -> A+ | G8: =IF(E8>=80,5, IF(E8>=70,4, IF(E8>=60,3.5, IF(E8>=50,3, IF(E8>=40,2, IF(E8>=33,1,0)))))) -> 5
B9: B.G.S | C9: ='6t'!I6 -> 23 | D9: ='6s'!I6 -> 63 | E9: =SUM(C9:D9) -> 86 | F9: =IF(E9>=80,"A+", IF(E9>=70,"A", IF(E9>=60,"A-", IF(E9>=50,"B", IF(E9>=40,"C", IF(E9>=33,"D","F")))))) -> A+ | G9: =IF(E9>=80,5, IF(E9>=70,4, IF(E9>=60,3.5, IF(E9>=50,3, IF(E9>=40,2, IF(E9>=33,1,0)))))) -> 5
B10: Agri. | C10: ='6t'!J6 -> 26 | D10: ='6s'!J6 -> 50 | E10: =SUM(C10:D10) -> 76 | F10: =IF(E10>=80,"A+", IF(E10>=70,"A", IF(E10>=60,"A-", IF(E10>=50,"B", IF(E10>=40,"C", IF(E10>=33,"D","F")))))) -> A | G10: =IF(E10>=80,5, IF(E10>=70,4, IF(E10>=60,3.5, IF(E10>=50,3, IF(E10>=40,2, IF(E10>=33,1,0)))))) -> 4
B11: Religion | C11: ='6t'!K6 -> 30 | D11: ='6s'!K6 -> 70 | E11: =SUM(C11:D11) -> 100 | F11: =IF(E11>=80,"A+", IF(E11>=70,"A", IF(E11>=60,"A-", IF(E11>=50,"B", IF(E11>=40,"C", IF(E11>=33,"D","F")))))) -> A+ | G11: =IF(E11>=80,5, IF(E11>=70,4, IF(E11>=60,3.5, IF(E11>=50,3, IF(E11>=40,2, IF(E11>=33,1,0)))))) -> 5
B12: ICT | C12: ='6t'!L6 -> 13 | D12: ='6s'!L6 -> 13 | E12: =SUM(C12:D12) -> 26 | F12: =IF(E12>=40,"A+", IF(E12>=35,"A", IF(E12>=30,"A-", IF(E12>=25,"B", IF(E12>=20,"C", IF(E12>=16,"D","F")))))) -> B | G12: =IF(E12>=40,5, IF(E12>=35,4, IF(E12>=30,3.5, IF(E12>=25,3, IF(E12>=20,2, IF(E12>=16,1,0)))))) -> 3
A13: SN | B13: Student’s Name | C13: ='6s'!B7 -> JENIYA AKTER
A14: 2 | B14: Subject’s Name | C14: ='6'!C2 -> 3rd Tutorial Exam (30) | D14: ='6'!D2 -> 3rd Semester Exam (70) | E14: Total Marks | F14: Grade Letter | G14: Grade Point | H14: G.P.A
B15: Bangla-1 | C15: ='6t'!C7 -> 20 | D15: ='6s'!C7 -> 32 | E15: =SUM(C15:D15) -> 52 | F15: =IF(E15>=80,"A+", IF(E15>=70,"A", IF(E15>=60,"A-", IF(E15>=50,"B", IF(E15>=40,"C", IF(E15>=33,"D","F")))))) -> B | G15: =IF(E15>=80,5, IF(E15>=70,4, IF(E15>=60,3.5, IF(E15>=50,3, IF(E15>=40,2, IF(E15>=33,1,0)))))) -> 3 | H15: =AVERAGE( VALUE(G15), VALUE(G16), VALUE(G17), VALUE(G18), VALUE(G19), VALUE(G20), VALUE(G21), VALUE(G22), VALUE(G23), VALUE(G24)) -> 3.45
B16: Bangla-2 | C16: ='6t'!D7 | D16: ='6s'!D7 -> 44 | E16: =SUM(C16:D16) -> 44 | F16: =IF(E16>=40,"A+", IF(E16>=35,"A", IF(E16>=30,"A-", IF(E16>=25,"B", IF(E16>=20,"C", IF(E16>=16,"D","F")))))) -> A+ | G16: =IF(E16>=40,5, IF(E16>=35,4, IF(E16>=30,3.5, IF(E16>=25,3, IF(E16>=20,2, IF(E16>=16,1,0)))))) -> 5
B17: English-1 | C17: ='6t'!E7 -> 13 | D17: ='6s'!E7 -> 40 | E17: =SUM(C17:D17) -> 53 | F17: =IF(E17>=80,"A+", IF(E17>=70,"A", IF(E17>=60,"A-", IF(E17>=50,"B", IF(E17>=40,"C", IF(E17>=33,"D","F")))))) -> B | G17: =IF(E17>=80,5, IF(E17>=70,4, IF(E17>=60,3.5, IF(E17>=50,3, IF(E17>=40,2, IF(E17>=33,1,0)))))) -> 3
B18: English-2 | C18: ='6t'!F7 | D18: ='6s'!F7 -> 25 | E18: =SUM(C18:D18) -> 25 | F18: =IF(E18>=40,"A+", IF(E18>=35,"A", IF(E18>=30,"A-", IF(E18>=25,"B", IF(E18>=20,"C", IF(E18>=16,"D","F")))))) -> B | G18: =IF(E18>=40,5, IF(E18>=35,4, IF(E18>=30,3.5, IF(E18>=25,3, IF(E18>=20,2, IF(E18>=16,1,0)))))) -> 3
B19: Mathematics | C19: ='6t'!G7 -> 18 | D19: ='6s'!G7 -> 34 | E19: =SUM(C19:D19) -> 52 | F19: =IF(E19>=80,"A+", IF(E19>=70,"A", IF(E19>=60,"A-", IF(E19>=50,"B", IF(E19>=40,"C", IF(E19>=33,"D","F")))))) -> B | G19: =IF(E19>=80,5, IF(E19>=70,4, IF(E19>=60,3.5, IF(E19>=50,3, IF(E19>=40,2, IF(E19>=33,1,0)))))) -> 3
B20: Science | C20: ='6t'!H7 -> 26 | D20: ='6s'!H7 -> 38 | E20: =SUM(C20:D20) -> 64 | F20: =IF(E20>=80,"A+", IF(E20>=70,"A", IF(E20>=60,"A-", IF(E20>=50,"B", IF(E20>=40,"C", IF(E20>=33,"D","F")))))) -> A- | G20: =IF(E20>=80,5, IF(E20>=70,4, IF(E20>=60,3.5, IF(E20>=50,3, IF(E20>=40,2, IF(E20>=33,1,0)))))) -> 3.5
B21: B.G.S | C21: ='6t'!I7 -> 19 | D21: ='6s'!I7 -> 53 | E21: =SUM(C21:D21) -> 72 | F21: =IF(E21>=80,"A+", IF(E21>=70,"A", IF(E21>=60,"A-", IF(E21>=50,"B", IF(E21>=40,"C", IF(E21>=33,"D","F")))))) -> A | G21: =IF(E21>=80,5, IF(E21>=70,4, IF(E21>=60,3.5, IF(E21>=50,3, IF(E21>=40,2, IF(E21>=33,1,0)))))) -> 4
B22: Agri. | C22: ='6t'!J7 -> 24 | D22: ='6s'!J7 -> 26 | E22: =SUM(C22:D22) -> 50 | F22: =IF(E22>=80,"A+", IF(E22>=70,"A", IF(E22>=60,"A-", IF(E22>=50,"B", IF(E22>=40,"C", IF(E22>=33,"D","F")))))) -> B | G22: =IF(E22>=80,5, IF(E22>=70,4, IF(E22>=60,3.5, IF(E22>=50,3, IF(E22>=40,2, IF(E22>=33,1,0)))))) -> 3
B23: Religion | C23: ='6t'!K7 -> 26 | D23: ='6s'!K7 -> 62 | E23: =SUM(C23:D23) -> 88 | F23: =IF(E23>=80,"A+", IF(E23>=70,"A", IF(E23>=60,"A-", IF(E23>=50,"B", IF(E23>=40,"C", IF(E23>=33,"D","F")))))) -> A+ | G23: =IF(E23>=80,5, IF(E23>=70,4, IF(E23>=60,3.5, IF(E23>=50,3, IF(E23>=40,2, IF(E23>=33,1,0)))))) -> 5
B24: ICT | C24: ='6t'!L7 -> 12 | D24: ='6s'!L7 -> 12 | E24: =SUM(C24:D24) -> 24 | F24: =IF(E24>=40,"A+", IF(E24>=35,"A", IF(E24>=30,"A-", IF(E24>=25,"B", IF(E24>=20,"C", IF(E24>=16,"D","F")))))) -> C | G24: =IF(E24>=40,5, IF(E24>=35,4, IF(E24>=30,3.5, IF(E24>=25,3, IF(E24>=20,2, IF(E24>=16,1,0)))))) -> 2
A25: SN | B25: Student’s Name | C25: ='6s'!B8 -> FATEMA AKTER
A26: 3 | B26: Subject’s Name | C26: ='6'!C14 -> 3rd Tutorial Exam (30) | D26: ='6'!D14 -> 3rd Semester Exam (70) | E26: Total Marks | F26: Grade Letter | G26: Grade Point | H26: G.P.A
B27: Bangla-1 | C27: ='6t'!C8 -> 10 | D27: ='6s'!C8 -> 25 | E27: =SUM(C27:D27) -> 35 | F27: =IF(E27>=80,"A+", IF(E27>=70,"A", IF(E27>=60,"A-", IF(E27>=50,"B", IF(E27>=40,"C", IF(E27>=33,"D","F")))))) -> D | G27: =IF(E27>=80,5, IF(E27>=70,4, IF(E27>=60,3.5, IF(E27>=50,3, IF(E27>=40,2, IF(E27>=33,1,0)))))) -> 1 | H27: =AVERAGE( VALUE(G27), VALUE(G28), VALUE(G29), VALUE(G30), VALUE(G31), VALUE(G32), VALUE(G33), VALUE(G34), VALUE(G35), VALUE(G36)) -> 1.4
B28: Bangla-2 | C28: ='6t'!D8 | D28: ='6s'!D8 -> 16 | E28: =SUM(C28:D28) -> 16 | F28: =IF(E28>=40,"A+", IF(E28>=35,"A", IF(E28>=30,"A-", IF(E28>=25,"B", IF(E28>=20,"C", IF(E28>=16,"D","F")))))) -> D | G28: =IF(E28>=40,5, IF(E28>=35,4, IF(E28>=30,3.5, IF(E28>=25,3, IF(E28>=20,2, IF(E28>=16,1,0)))))) -> 1
B29: English-1 | C29: ='6t'!E8 -> 10 | D29: ='6s'!E8 -> 25 | E29: =SUM(C29:D29) -> 35 | F29: =IF(E29>=80,"A+", IF(E29>=70,"A", IF(E29>=60,"A-", IF(E29>=50,"B", IF(E29>=40,"C", IF(E29>=33,"D","F")))))) -> D | G29: =IF(E29>=80,5, IF(E29>=70,4, IF(E29>=60,3.5, IF(E29>=50,3, IF(E29>=40,2, IF(E29>=33,1,0)))))) -> 1
B30: English-2 | C30: ='6t'!F8 | D30: ='6s'!F8 -> 25 | E30: =SUM(C30:D30) -> 25 | F30: =IF(E30>=40,"A+", IF(E30>=35,"A", IF(E30>=30,"A-", IF(E30>=25,"B", IF(E30>=20,"C", IF(E30>=16,"D","F")))))) -> B | G30: =IF(E30>=40,5, IF(E30>=35,4, IF(E30>=30,3.5, IF(E30>=25,3, IF(E30>=20,2, IF(E30>=16,1,0)))))) -> 3
B31: Mathematics | C31: ='6t'!G8 | D31: ='6s'!G8 | E31: =SUM(C31:D31) -> 0 | F31: =IF(E31>=80,"A+", IF(E31>=70,"A", IF(E31>=60,"A-", IF(E31>=50,"B", IF(E31>=40,"C", IF(E31>=33,"D","F")))))) -> F | G31: =IF(E31>=80,5, IF(E31>=70,4, IF(E31>=60,3.5, IF(E31>=50,3, IF(E31>=40,2, IF(E31>=33,1,0)))))) -> 0
B32: Science | C32: ='6t'!H8 -> 10 | D32: ='6s'!H8 -> 33 | E32: =SUM(C32:D32) -> 43 | F32: =IF(E32>=80,"A+", IF(E32>=70,"A", IF(E32>=60,"A-", IF(E32>=50,"B", IF(E32>=40,"C", IF(E32>=33,"D","F")))))) -> C | G32: =IF(E32>=80,5, IF(E32>=70,4, IF(E32>=60,3.5, IF(E32>=50,3, IF(E32>=40,2, IF(E32>=33,1,0)))))) -> 2
B33: B.G.S | C33: ='6t'!I8 | D33: ='6s'!I8 -> 40 | E33: =SUM(C33:D33) -> 40 | F33: =IF(E33>=80,"A+", IF(E33>=70,"A", IF(E33>=60,"A-", IF(E33>=50,"B", IF(E33>=40,"C", IF(E33>=33,"D","F")))))) -> C | G33: =IF(E33>=80,5, IF(E33>=70,4, IF(E33>=60,3.5, IF(E33>=50,3, IF(E33>=40,2, IF(E33>=33,1,0)))))) -> 2
B34: Agri. | C34: ='6t'!J8 -> 22 | D34: ='6s'!J8 -> 25 | E34: =SUM(C34:D34) -> 47 | F34: =IF(E34>=80,"A+", IF(E34>=70,"A", IF(E34>=60,"A-", IF(E34>=50,"B", IF(E34>=40,"C", IF(E34>=33,"D","F")))))) -> C | G34: =IF(E34>=80,5, IF(E34>=70,4, IF(E34>=60,3.5, IF(E34>=50,3, IF(E34>=40,2, IF(E34>=33,1,0)))))) -> 2
B35: Religion | C35: ='6t'!K8 -> 16 | D35: ='6s'!K8 -> 26 | E35: =SUM(C35:D35) -> 42 | F35: =IF(E35>=80,"A+", IF(E35>=70,"A", IF(E35>=60,"A-", IF(E35>=50,"B", IF(E35>=40,"C", IF(E35>=33,"D","F")))))) -> C | G35: =IF(E35>=80,5, IF(E35>=70,4, IF(E35>=60,3.5, IF(E35>=50,3, IF(E35>=40,2, IF(E35>=33,1,0)))))) -> 2
B36: ICT | C36: ='6t'!L8 -> 8 | D36: ='6s'!L8 | E36: =SUM(C36:D36) -> 8 | F36: =IF(E36>=40,"A+", IF(E36>=35,"A", IF(E36>=30,"A-", IF(E36>=25,"B", IF(E36>=20,"C", IF(E36>=16,"D","F")))))) -> F | G36: =IF(E36>=40,5, IF(E36>=35,4, IF(E36>=30,3.5, IF(E36>=25,3, IF(E36>=20,2, IF(E36>=16,1,0)))))) -> 0
A37: SN | B37: Student’s Name | C37: ='6s'!B9 -> USAMA
A38: 4 | B38: Subject’s Name | C38: ='6'!C26 -> 3rd Tutorial Exam (30) | D38: ='6'!D26 -> 3rd Semester Exam (70) | E38: Total Marks | F38: Grade Letter | G38: Grade Point | H38: G.P.A
B39: Bangla-1 | C39: ='6t'!C9 -> 10 | D39: ='6s'!C9 -> 24 | E39: =SUM(C39:D39) -> 34 | F39: =IF(E39>=80,"A+", IF(E39>=70,"A", IF(E39>=60,"A-", IF(E39>=50,"B", IF(E39>=40,"C", IF(E39>=33,"D","F")))))) -> D | G39: =IF(E39>=80,5, IF(E39>=70,4, IF(E39>=60,3.5, IF(E39>=50,3, IF(E39>=40,2, IF(E39>=33,1,0)))))) -> 1 | H39: =AVERAGE( VALUE(G39), VALUE(G40), VALUE(G41), VALUE(G42), VALUE(G43), VALUE(G44), VALUE(G45), VALUE(G46), VALUE(G47), VALUE(G48)) -> 1.3
B40: Bangla-2 | C40: ='6t'!D9 | D40: ='6s'!D9 -> 16 | E40: =SUM(C40:D40) -> 16 | F40: =IF(E40>=40,"A+", IF(E40>=35,"A", IF(E40>=30,"A-", IF(E40>=25,"B", IF(E40>=20,"C", IF(E40>=16,"D","F")))))) -> D | G40: =IF(E40>=40,5, IF(E40>=35,4, IF(E40>=30,3.5, IF(E40>=25,3, IF(E40>=20,2, IF(E40>=16,1,0)))))) -> 1
...

Sheet 6r
A1: Hemayetpur Laboratory School and College
A2: Annual Examination Results-2025
A3: Class: Six
A4: SN | B4: Student’s Name | C4: Rank
C5: G.P.A | D5: Rank
A6: 1 | B6: RIYA MONI | C6: ='6'!H3 -> 4.6 | D6: =RANK(C6,$C$6:$C$12) -> 1
A7: 2 | B7: JENIYA AKTER | C7: ='6'!H15 -> 3.45 | D7: =RANK(C7,$C$6:$C$12) -> 2
A8: 3 | B8: FATEMA AKTER | C8: ='6'!H27 -> 1.4 | D8: =RANK(C8,$C$6:$C$12) -> 3
A9: 4 | B9: USAMA | C9: ='6'!H39 -> 1.3 | D9: =RANK(C9,$C$6:$C$12) -> 4
A10: 5 | B10: SHAHABIR | C10: ='6'!H51 -> 1.1 | D10: =RANK(C10,$C$6:$C$12) -> 5
A11: 6 | B11: MIM AKTER SHATHI | C11: ='6'!H63 -> 0.3 | D11: =RANK(C11,$C$6:$C$12) -> 7
A12: 7 | B12: ETI PRIYA | C12: ='6'!H75 -> 0.6 | D12: =RANK(C12,$C$6:$C$12) -> 6

Sheet 7t
A1: Hemayetpur Laboratory School and College
A2: 3rd Tutorial Examination Marksheet-2025
A3: Class: Seven
A4: SN | B4: Student’s Name | C4: Subject’s Name & Marks
C5: Bangla-1 | D5: Bangla-2 | E5: English -1 | F5: English -2 | G5: Math. | H5: Science | I5: B.G.S | J5: Agri. | K5: Religion | L5: ICT | M5: Total | N5: Rank
A6: 1 | B6: RAFIYA AKTER | C6: 30 | E6: 30 | G6: 30 | H6: 30 | I6: 30 | J6: 27 | K6: 30 | L6: 20 | M6: =SUM(C6:L6) -> 227 | N6: =RANK(M6,$M$6:$M$11) -> 1
A7: 2 | B7: MASUMA AKTER | C7: 25 | E7: 27 | G7: 30 | H7: 28 | I7: 23 | J7: 27 | K7: 24 | L7: 19 | M7: =SUM(C7:L7) -> 203 | N7: =RANK(M7,$M$6:$M$11) -> 2
A8: 3 | B8: SUMAYIA AKTER | C8: 10 | E8: 10 | G8: 10 | H8: 10 | I8: 10 | J8: 11 | K8: 10 | L8: 8 | M8: =SUM(C8:L8) -> 79 | N8: =RANK(M8,$M$6:$M$11) -> 4
A9: 4 | B9: JANNAT AKTER | M9: =SUM(C9:L9) -> 0 | N9: =RANK(M9,$M$6:$M$11) -> 6
A10: 5 | B10: SUMONA AKTER | C10: 10 | E10: 10 | I10: 10 | J10: 13 | K10: 10 | L10: 12 | M10: =SUM(C10:L10) -> 65 | N10: =RANK(M10,$M$6:$M$11) -> 5
A11: 6 | B11: SHOWRIN SHABA | C11: 13 | E11: 27 | G11: 20 | H11: 22 | I11: 13 | J11: 21 | K11: 14 | L11: 15 | M11: =SUM(C11:L11) -> 145 | N11: =RANK(M11,$M$6:$M$11) -> 3

Sheet 7s
A1: Hemayetpur Laboratory School and College
A2: Annual Examination Marksheet-2025
A3: Class: Seven
A4: SN | B4: Student’s Name | C4: Subject’s Name & Marks
C5: Bangla-1 | D5: Bangla-2 | E5: English -1 | F5: English -2 | G5: Math. | H5: Science | I5: B.G.S | J5: Agri. | K5: Religion | L5: ICT | M5: Total | N5: Rank
A6: 1 | B6: RAFIYA AKTER | C6: 62 | D6: 35 | F6: 45 | G6: 66 | H6: 52 | I6: 56 | J6: 56 | K6: 64 | L6: 20 | M6: =SUM(C6:L6) -> 456 | N6: =RANK(M6,$M$6:$M$11) -> 1
A7: 2 | B7: MASUMA AKTER | C7: 45 | D7: 22 | E7: 50 | F7: 35 | G7: 60 | H7: 40 | I7: 46 | J7: 53 | K7: 50 | L7: 19 | M7: =SUM(C7:L7) -> 420 | N7: =RANK(M7,$M$6:$M$11) -> 2
A8: 3 | B8: SUMAYIA AKTER | C8: 24 | D8: 17 | E8: 25 | F8: 25 | G8: 24 | H8: 24 | I8: 28 | J8: 24 | K8: 26 | L8: 8 | M8: =SUM(C8:L8) -> 225 | N8: =RANK(M8,$M$6:$M$11) -> 4
A9: 4 | B9: JANNAT AKTER | M9: =SUM(C9:L9) -> 0 | N9: =RANK(M9,$M$6:$M$11) -> 6
A10: 5 | B10: SUMONA AKTER | C10: 24 | D10: 17 | E10: 25 | F10: 25 | G10: 24 | H10: 24 | I10: 24 | J10: 24 | K10: 26 | L10: 12 | M10: =SUM(C10:L10) -> 225 | N10: =RANK(M10,$M$6:$M$11) -> 4
A11: 6 | B11: SHOWRIN SHABA | C11: 36 | D11: 18 | E11: 30 | F11: 33 | G11: 62 | H11: 31 | I11: 32 | J11: 43 | K11: 33 | L11: 15 | M11: =SUM(C11:L11) -> 333 | N11: =RANK(M11,$M$6:$M$11) -> 3

Sheet 7
A1: SN | B1: Student’s Name | C1: ='7s'!B6 -> RAFIYA AKTER
A2: 1 | B2: Subject’s Name | C2: 3rd Tutorial Exam (30) | D2: 3rd Semester Exam (70) | E2: Total Marks | F2: Grade Letter | G2: Grade Point | H2: G.P.A
B3: Bangla-1 | C3: ='7t'!C6 -> 30 | D3: ='7s'!C6 -> 62 | E3: =SUM(C3:D3) -> 92 | F3: =IF(E3>=80,"A+", IF(E3>=70,"A", IF(E3>=60,"A-", IF(E3>=50,"B", IF(E3>=40,"C", IF(E3>=33,"D","F")))))) -> A+ | G3: =IF(E3>=80,5, IF(E3>=70,4, IF(E3>=60,3.5, IF(E3>=50,3, IF(E3>=40,2, IF(E3>=33,1,0)))))) -> 5 | H3: =AVERAGE( VALUE(G3), VALUE(G4), VALUE(G5), VALUE(G6), VALUE(G7), VALUE(G8), VALUE(G9), VALUE(G10), VALUE(G11), VALUE(G12)) -> 4.4
B4: Bangla-2 | C4: ='7t'!D6 | D4: ='7s'!D6 -> 35 | E4: =SUM(C4:D4) -> 35 | F4: =IF(E4>=40,"A+", IF(E4>=35,"A", IF(E4>=30,"A-", IF(E4>=25,"B", IF(E4>=20,"C", IF(E4>=16,"D","F")))))) -> A | G4: =IF(E4>=40,5, IF(E4>=35,4, IF(E4>=30,3.5, IF(E4>=25,3, IF(E4>=20,2, IF(E4>=16,1,0)))))) -> 4
B5: English-1 | C5: ='7t'!E6 -> 30 | D5: ='7s'!E6 | E5: =SUM(C5:D5) -> 30 | F5: =IF(E5>=80,"A+", IF(E5>=70,"A", IF(E5>=60,"A-", IF(E5>=50,"B", IF(E5>=40,"C", IF(E5>=33,"D","F")))))) -> F | G5: =IF(E5>=80,5, IF(E5>=70,4, IF(E5>=60,3.5, IF(E5>=50,3, IF(E5>=40,2, IF(E5>=33,1,0)))))) -> 0
B6: English-2 | C6: ='7t'!F6 | D6: ='7s'!F6 -> 45 | E6: =SUM(C6:D6) -> 45 | F6: =IF(E6>=40,"A+", IF(E6>=35,"A", IF(E6>=30,"A-", IF(E6>=25,"B", IF(E6>=20,"C", IF(E6>=16,"D","F")))))) -> A+ | G6: =IF(E6>=40,5, IF(E6>=35,4, IF(E6>=30,3.5, IF(E6>=25,3, IF(E6>=20,2, IF(E6>=16,1,0)))))) -> 5
B7: Mathematics | C7: ='7t'!G6 -> 30 | D7: ='7s'!G6 -> 66 | E7: =SUM(C7:D7) -> 96 | F7: =IF(E7>=80,"A+", IF(E7>=70,"A", IF(E7>=60,"A-", IF(E7>=50,"B", IF(E7>=40,"C", IF(E7>=33,"D","F")))))) -> A+ | G7: =IF(E7>=80,5, IF(E7>=70,4, IF(E7>=60,3.5, IF(E7>=50,3, IF(E7>=40,2, IF(E7>=33,1,0)))))) -> 5
B8: Science | C8: ='7t'!H6 -> 30 | D8: ='7s'!H6 -> 52 | E8: =SUM(C8:D8) -> 82 | F8: =IF(E8>=80,"A+", IF(E8>=70,"A", IF(E8>=60,"A-", IF(E8>=50,"B", IF(E8>=40,"C", IF(E8>=33,"D","F")))))) -> A+ | G8: =IF(E8>=80,5, IF(E8>=70,4, IF(E8>=60,3.5, IF(E8>=50,3, IF(E8>=40,2, IF(E8>=33,1,0)))))) -> 5
B9: B.G.S | C9: ='7t'!I6 -> 30 | D9: ='7s'!I6 -> 56 | E9: =SUM(C9:D9) -> 86 | F9: =IF(E9>=80,"A+", IF(E9>=70,"A", IF(E9>=60,"A-", IF(E9>=50,"B", IF(E9>=40,"C", IF(E9>=33,"D","F")))))) -> A+ | G9: =IF(E9>=80,5, IF(E9>=70,4, IF(E9>=60,3.5, IF(E9>=50,3, IF(E9>=40,2, IF(E9>=33,1,0)))))) -> 5
B10: Agri. | C10: ='7t'!J6 -> 27 | D10: ='7s'!J6 -> 56 | E10: =SUM(C10:D10) -> 83 | F10: =IF(E10>=80,"A+", IF(E10>=70,"A", IF(E10>=60,"A-", IF(E10>=50,"B", IF(E10>=40,"C", IF(E10>=33,"D","F")))))) -> A+ | G10: =IF(E10>=80,5, IF(E10>=70,4, IF(E10>=60,3.5, IF(E10>=50,3, IF(E10>=40,2, IF(E10>=33,1,0)))))) -> 5
B11: Religion | C11: ='7t'!K6 -> 30 | D11: ='7s'!K6 -> 64 | E11: =SUM(C11:D11) -> 94 | F11: =IF(E11>=80,"A+", IF(E11>=70,"A", IF(E11>=60,"A-", IF(E11>=50,"B", IF(E11>=40,"C", IF(E11>=33,"D","F")))))) -> A+ | G11: =IF(E11>=80,5, IF(E11>=70,4, IF(E11>=60,3.5, IF(E11>=50,3, IF(E11>=40,2, IF(E11>=33,1,0)))))) -> 5
B12: ICT | C12: ='7t'!L6 -> 20 | D12: ='7s'!L6 -> 20 | E12: =SUM(C12:D12) -> 40 | F12: =IF(E12>=40,"A+", IF(E12>=35,"A", IF(E12>=30,"A-", IF(E12>=25,"B", IF(E12>=20,"C", IF(E12>=16,"D","F")))))) -> A+ | G12: =IF(E12>=40,5, IF(E12>=35,4, IF(E12>=30,3.5, IF(E12>=25,3, IF(E12>=20,2, IF(E12>=16,1,0)))))) -> 5
A13: SN | B13: Student’s Name | C13: ='7s'!B7 -> MASUMA AKTER
A14: 2 | B14: Subject’s Name | C14: ='7'!C2 -> 3rd Tutorial Exam (30) | D14: ='7'!D2 -> 3rd Semester Exam (70) | E14: Total Marks | F14: Grade Letter | G14: Grade Point | H14: G.P.A
B15: Bangla-1 | C15: ='7t'!C7 -> 25 | D15: ='7s'!C7 -> 45 | E15: =SUM(C15:D15) -> 70 | F15: =IF(E15>=80,"A+", IF(E15>=70,"A", IF(E15>=60,"A-", IF(E15>=50,"B", IF(E15>=40,"C", IF(E15>=33,"D","F")))))) -> A | G15: =IF(E15>=80,5, IF(E15>=70,4, IF(E15>=60,3.5, IF(E15>=50,3, IF(E15>=40,2, IF(E15>=33,1,0)))))) -> 4 | H15: =AVERAGE( VALUE(G15), VALUE(G16), VALUE(G17), VALUE(G18), VALUE(G19), VALUE(G20), VALUE(G21), VALUE(G22), VALUE(G23), VALUE(G24)) -> 3.9
B16: Bangla-2 | C16: ='7t'!D7 | D16: ='7s'!D7 -> 22 | E16: =SUM(C16:D16) -> 22 | F16: =IF(E16>=40,"A+", IF(E16>=35,"A", IF(E16>=30,"A-", IF(E16>=25,"B", IF(E16>=20,"C", IF(E16>=16,"D","F")))))) -> C | G16: =IF(E16>=40,5, IF(E16>=35,4, IF(E16>=30,3.5, IF(E16>=25,3, IF(E16>=20,2, IF(E16>=16,1,0)))))) -> 2
B17: English-1 | C17: ='7t'!E7 -> 27 | D17: ='7s'!E7 -> 50 | E17: =SUM(C17:D17) -> 77 | F17: =IF(E17>=80,"A+", IF(E17>=70,"A", IF(E17>=60,"A-", IF(E17>=50,"B", IF(E17>=40,"C", IF(E17>=33,"D","F")))))) -> A | G17: =IF(E17>=80,5, IF(E17>=70,4, IF(E17>=60,3.5, IF(E17>=50,3, IF(E17>=40,2, IF(E17>=33,1,0)))))) -> 4
B18: English-2 | C18: ='7t'!F7 | D18: ='7s'!F7 -> 35 | E18: =SUM(C18:D18) -> 35 | F18: =IF(E18>=40,"A+", IF(E18>=35,"A", IF(E18>=30,"A-", IF(E18>=25,"B", IF(E18>=20,"C", IF(E18>=16,"D","F")))))) -> A | G18: =IF(E18>=40,5, IF(E18>=35,4, IF(E18>=30,3.5, IF(E18>=25,3, IF(E18>=20,2, IF(E18>=16,1,0)))))) -> 4
B19: Mathematics | C19: ='7t'!G7 -> 30 | D19: ='7s'!G7 -> 60 | E19: =SUM(C19:D19) -> 90 | F19: =IF(E19>=80,"A+", IF(E19>=70,"A", IF(E19>=60,"A-", IF(E19>=50,"B", IF(E19>=40,"C", IF(E19>=33,"D","F")))))) -> A+ | G19: =IF(E19>=80,5, IF(E19>=70,4, IF(E19>=60,3.5, IF(E19>=50,3, IF(E19>=40,2, IF(E19>=33,1,0)))))) -> 5
B20: Science | C20: ='7t'!H7 -> 28 | D20: ='7s'!H7 -> 40 | E20: =SUM(C20:D20) -> 68 | F20: =IF(E20>=80,"A+", IF(E20>=70,"A", IF(E20>=60,"A-", IF(E20>=50,"B", IF(E20>=40,"C", IF(E20>=33,"D","F")))))) -> A- | G20: =IF(E20>=80,5, IF(E20>=70,4, IF(E20>=60,3.5, IF(E20>=50,3, IF(E20>=40,2, IF(E20>=33,1,0)))))) -> 3.5
B21: B.G.S | C21: ='7t'!I7 -> 23 | D21: ='7s'!I7 -> 46 | E21: =SUM(C21:D21) -> 69 | F21: =IF(E21>=80,"A+", IF(E21>=70,"A", IF(E21>=60,"A-", IF(E21>=50,"B", IF(E21>=40,"C", IF(E21>=33,"D","F")))))) -> A- | G21: =IF(E21>=80,5, IF(E21>=70,4, IF(E21>=60,3.5, IF(E21>=50,3, IF(E21>=40,2, IF(E21>=33,1,0)))))) -> 3.5
B22: Agri. | C22: ='7t'!J7 -> 27 | D22: ='7s'!J7 -> 53 | E22: =SUM(C22:D22) -> 80 | F22: =IF(E22>=80,"A+", IF(E22>=70,"A", IF(E22>=60,"A-", IF(E22>=50,"B", IF(E22>=40,"C", IF(E22>=33,"D","F")))))) -> A+ | G22: =IF(E22>=80,5, IF(E22>=70,4, IF(E22>=60,3.5, IF(E22>=50,3, IF(E22>=40,2, IF(E22>=33,1,0)))))) -> 5
B23: Religion | C23: ='7t'!K7 -> 24 | D23: ='7s'!K7 -> 50 | E23: =SUM(C23:D23) -> 74 | F23: =IF(E23>=80,"A+", IF(E23>=70,"A", IF(E23>=60,"A-", IF(E23>=50,"B", IF(E23>=40,"C", IF(E23>=33,"D","F")))))) -> A | G23: =IF(E23>=80,5, IF(E23>=70,4, IF(E23>=60,3.5, IF(E23>=50,3, IF(E23>=40,2, IF(E23>=33,1,0)))))) -> 4
B24: ICT | C24: ='7t'!L7 -> 19 | D24: ='7s'!L7 -> 19 | E24: =SUM(C24:D24) -> 38 | F24: =IF(E24>=40,"A+", IF(E24>=35,"A", IF(E24>=30,"A-", IF(E24>=25,"B", IF(E24>=20,"C", IF(E24>=16,"D","F")))))) -> A | G24: =IF(E24>=40,5, IF(E24>=35,4, IF(E24>=30,3.5, IF(E24>=25,3, IF(E24>=20,2, IF(E24>=16,1,0)))))) -> 4
A25: SN | B25: Student’s Name | C25: ='7s'!B8 -> SUMAYIA AKTER
A26: 3 | B26: Subject’s Name | C26: ='7'!C14 -> 3rd Tutorial Exam (30) | D26: ='7'!D14 -> 3rd Semester Exam (70) | E26: Total Marks | F26: Grade Letter | G26: Grade Point | H26: G.P.A
B27: Bangla-1 | C27: ='7t'!C8 -> 10 | D27: ='7s'!C8 -> 24 | E27: =SUM(C27:D27) -> 34 | F27: =IF(E27>=80,"A+", IF(E27>=70,"A", IF(E27>=60,"A-", IF(E27>=50,"B", IF(E27>=40,"C", IF(E27>=33,"D","F")))))) -> D | G27: =IF(E27>=80,5, IF(E27>=70,4, IF(E27>=60,3.5, IF(E27>=50,3, IF(E27>=40,2, IF(E27>=33,1,0)))))) -> 1 | H27: =AVERAGE( VALUE(G27), VALUE(G28), VALUE(G29), VALUE(G30), VALUE(G31), VALUE(G32), VALUE(G33), VALUE(G34), VALUE(G35), VALUE(G36)) -> 1.2
B28: Bangla-2 | C28: ='7t'!D8 | D28: ='7s'!D8 -> 17 | E28: =SUM(C28:D28) -> 17 | F28: =IF(E28>=40,"A+", IF(E28>=35,"A", IF(E28>=30,"A-", IF(E28>=25,"B", IF(E28>=20,"C", IF(E28>=16,"D","F")))))) -> D | G28: =IF(E28>=40,5, IF(E28>=35,4, IF(E28>=30,3.5, IF(E28>=25,3, IF(E28>=20,2, IF(E28>=16,1,0)))))) -> 1
B29: English-1 | C29: ='7t'!E8 -> 10 | D29: ='7s'!E8 -> 25 | E29: =SUM(C29:D29) -> 35 | F29: =IF(E29>=80,"A+", IF(E29>=70,"A", IF(E29>=60,"A-", IF(E29>=50,"B", IF(E29>=40,"C", IF(E29>=33,"D","F")))))) -> D | G29: =IF(E29>=80,5, IF(E29>=70,4, IF(E29>=60,3.5, IF(E29>=50,3, IF(E29>=40,2, IF(E29>=33,1,0)))))) -> 1
B30: English-2 | C30: ='7t'!F8 | D30: ='7s'!F8 -> 25 | E30: =SUM(C30:D30) -> 25 | F30: =IF(E30>=40,"A+", IF(E30>=35,"A", IF(E30>=30,"A-", IF(E30>=25,"B", IF(E30>=20,"C", IF(E30>=16,"D","F")))))) -> B | G30: =IF(E30>=40,5, IF(E30>=35,4, IF(E30>=30,3.5, IF(E30>=25,3, IF(E30>=20,2, IF(E30>=16,1,0)))))) -> 3
B31: Mathematics | C31: ='7t'!G8 -> 10 | D31: ='7s'!G8 -> 24 | E31: =SUM(C31:D31) -> 34 | F31: =IF(E31>=80,"A+", IF(E31>=70,"A", IF(E31>=60,"A-", IF(E31>=50,"B", IF(E31>=40,"C", IF(E31>=33,"D","F")))))) -> D | G31: =IF(E31>=80,5, IF(E31>=70,4, IF(E31>=60,3.5, IF(E31>=50,3, IF(E31>=40,2, IF(E31>=33,1,0)))))) -> 1
B32: Science | C32: ='7t'!H8 -> 10 | D32: ='7s'!H8 -> 24 | E32: =SUM(C32:D32) -> 34 | F32: =IF(E32>=80,"A+", IF(E32>=70,"A", IF(E32>=60,"A-", IF(E32>=50,"B", IF(E32>=40,"C", IF(E32>=33,"D","F")))))) -> D | G32: =IF(E32>=80,5, IF(E32>=70,4, IF(E32>=60,3.5, IF(E32>=50,3, IF(E32>=40,2, IF(E32>=33,1,0)))))) -> 1
B33: B.G.S | C33: ='7t'!I8 -> 10 | D33: ='7s'!I8 -> 28 | E33: =SUM(C33:D33) -> 38 | F33: =IF(E33>=80,"A+", IF(E33>=70,"A", IF(E33>=60,"A-", IF(E33>=50,"B", IF(E33>=40,"C", IF(E33>=33,"D","F")))))) -> D | G33: =IF(E33>=80,5, IF(E33>=70,4, IF(E33>=60,3.5, IF(E33>=50,3, IF(E33>=40,2, IF(E33>=33,1,0)))))) -> 1
B34: Agriclutre | C34: ='7t'!J8 -> 11 | D34: ='7s'!J8 -> 24 | E34: =SUM(C34:D34) -> 35 | F34: =IF(E34>=80,"A+", IF(E34>=70,"A", IF(E34>=60,"A-", IF(E34>=50,"B", IF(E34>=40,"C", IF(E34>=33,"D","F")))))) -> D | G34: =IF(E34>=80,5, IF(E34>=70,4, IF(E34>=60,3.5, IF(E34>=50,3, IF(E34>=40,2, IF(E34>=33,1,0)))))) -> 1
B35: Religion | C35: ='7t'!K8 -> 10 | D35: ='7s'!K8 -> 26 | E35: =SUM(C35:D35) -> 36 | F35: =IF(E35>=80,"A+", IF(E35>=70,"A", IF(E35>=60,"A-", IF(E35>=50,"B", IF(E35>=40,"C", IF(E35>=33,"D","F")))))) -> D | G35: =IF(E35>=80,5, IF(E35>=70,4, IF(E35>=60,3.5, IF(E35>=50,3, IF(E35>=40,2, IF(E35>=33,1,0)))))) -> 1
B36: ICT | C36: ='7t'!L8 -> 8 | D36: ='7s'!L8 -> 8 | E36: =SUM(C36:D36) -> 16 | F36: =IF(E36>=40,"A+", IF(E36>=35,"A", IF(E36>=30,"A-", IF(E36>=25,"B", IF(E36>=20,"C", IF(E36>=16,"D","F")))))) -> D | G36: =IF(E36>=40,5, IF(E36>=35,4, IF(E36>=30,3.5, IF(E36>=25,3, IF(E36>=20,2, IF(E36>=16,1,0)))))) -> 1
A37: SN | B37: Student’s Name | C37: ='7s'!B9 -> JANNAT AKTER
A38: 4 | B38: Subject’s Name | C38: ='7'!C26 -> 3rd Tutorial Exam (30) | D38: ='7'!D26 -> 3rd Semester Exam (70) | E38: Total Marks | F38: Grade Letter | G38: Grade Point | H38: G.P.A
B39: Bangla-1 | C39: ='7t'!C9 | D39: ='7s'!C9 | E39: =SUM(C39:D39) -> 0 | F39: =IF(E39>=80,"A+", IF(E39>=70,"A", IF(E39>=60,"A-", IF(E39>=50,"B", IF(E39>=40,"C", IF(E39>=33,"D","F")))))) -> F | G39: =IF(E39>=80,5, IF(E39>=70,4, IF(E39>=60,3.5, IF(E39>=50,3, IF(E39>=40,2, IF(E39>=33,1,0)))))) -> 0 | H39: =AVERAGE( VALUE(G39), VALUE(G40), VALUE(G41), VALUE(G42), VALUE(G43), VALUE(G44), VALUE(G45), VALUE(G46), VALUE(G47), VALUE(G48)) -> 0
B40: Bangla-2 | C40: ='7t'!D9 | D40: ='7s'!D9 | E40: =SUM(C40:D40) -> 0 | F40: =IF(E40>=40,"A+", IF(E40>=35,"A", IF(E40>=30,"A-", IF(E40>=25,"B", IF(E40>=20,"C", IF(E40>=16,"D","F")))))) -> F | G40: =IF(E40>=40,5, IF(E40>=35,4, IF(E40>=30,3.5, IF(E40>=25,3, IF(E40>=20,2, IF(E40>=16,1,0)))))) -> 0
...

Sheet 7r
A1: Hemayetpur Laboratory School and College
A2: Annual Examination Results-2025
A3: Class: Seven
A4: SN | B4: Student’s Name | C4: Rank
C5: G.P.A | D5: Rank
A6: 1 | B6: RAFIYA AKTER | C6: ='7'!H3 -> 4.4 | D6: =RANK(C6,$C$6:$C$11) -> 1
A7: 2 | B7: MASUMA AKTER | C7: ='7'!H15 -> 3.9 | D7: =RANK(C7,$C$6:$C$11) -> 2
A8: 3 | B8: SUMAYIA AKTER | C8: ='7'!H27 -> 1.2 | D8: =RANK(C8,$C$6:$C$11) -> 4
A9: 4 | B9: JANNAT AKTER | C9: ='7'!H39 -> 0 | D9: =RANK(C9,$C$6:$C$11) -> 6
A10: 5 | B10: SUMONA AKTER | C10: ='7'!H51 -> 1.1 | D10: =RANK(C10,$C$6:$C$11) -> 5
A11: 6 | B11: SHOWRIN SHABA | C11: ='7'!H63 -> 2.85 | D11: =RANK(C11,$C$6:$C$11) -> 3

Sheet 8t
A1: Hemayetpur Laboratory School and College
A2: 3rd Tutorial Examination Marksheet-2025
A3: Class: Eight
A4: SN | B4: Student’s Name | C4: Subject’s Name & Marks
C5: Bangla-1 | D5: Bangla-2 | E5: English -1 | F5: English -2 | G5: Math. | H5: Science | I5: B.G.S | J5: Agri. | K5: Religion | L5: ICT | M5: Total | N5: Rank
A6: 1 | B6: TANVIN ISLAM | C6: 28 | E6: 10 | G6: 20 | H6: 18 | I6: 19 | J6: 30 | K6: 30 | L6: 17 | M6: =SUM(C6:L6) -> 172 | N6: =RANK(M6,$M$6:$M$17) -> 1
A7: 2 | B7: RAJU ISLAM | C7: 25 | E7: 10 | G7: 10 | J7: 20 | K7: 20 | L7: 17 | M7: =SUM(C7:K7) -> 85 | N7: =RANK(M7,$M$6:$M$17) -> 7
A8: 3 | B8: MAINUL ISLAM | C8: 15 | E8: 11 | G8: 10 | H8: 15 | I8: 14 | J8: 20 | K8: 18 | L8: 16 | M8: =SUM(C8:K8) -> 103 | N8: =RANK(M8,$M$6:$M$17) -> 5
A9: 4 | B9: MIM AKTER | C9: 12 | E9: 10 | G9: 10 | H9: 13 | I9: 13 | J9: 24 | K9: 25 | L9: 10 | M9: =SUM(C9:K9) -> 107 | N9: =RANK(M9,$M$6:$M$17) -> 4
A10: 5 | B10: ALIF HOSSAIN | C10: 10 | E10: 10 | G10: 10 | I10: 10 | J10: 10 | K10: 10 | L10: 14 | M10: =SUM(C10:L10) -> 74 | N10: =RANK(M10,$M$6:$M$17) -> 9
A11: 6 | B11: SIAM AHAMED | C11: 10 | E11: 10 | G11: 10 | I11: 10 | J11: 10 | K11: 10 | L11: 10 | M11: =SUM(C11:K11) -> 60 | N11: =RANK(M11,$M$6:$M$17) -> 11
A12: 7 | B12: SUMIYA AKTER | C12: 11 | E12: 10 | G12: 10 | H12: 10 | I12: 12 | J12: 10 | K12: 10 | L12: 10 | M12: =SUM(C12:L12) -> 83 | N12: =RANK(M12,$M$6:$M$17) -> 8
A13: 8 | B13: SAMIHA AKTER | C13: 10 | E13: 10 | G13: 10 | H13: 10 | I13: 10 | J13: 10 | K13: 10 | L13: 9 | M13: =SUM(C13:K13) -> 70 | N13: =RANK(M13,$M$6:$M$17) -> 10
A14: 9 | B14: TASMIYA AKTER | C14: 11 | E14: 10 | G14: 10 | H14: 10 | I14: 10 | J14: 17 | K14: 17 | L14: 10 | M14: =SUM(C14:L14) -> 95 | N14: =RANK(M14,$M$6:$M$17) -> 6
A15: 10 | B15: SHKIL | C15: 17 | E15: 18 | G15: 10 | H15: 14 | I15: 18 | J15: 30 | K15: 29 | L15: 11 | M15: =SUM(C15:K15) -> 136 | N15: =RANK(M15,$M$6:$M$17) -> 2
A16: 11 | B16: RAKIB HASAN | L16: 16 | M16: =SUM(C16:K16) -> 0 | N16: =RANK(M16,$M$6:$M$17) -> 12
A17: 12 | B17: SOUROV ISLAM | C17: 15 | E17: 18 | G17: 23 | H17: 17 | I17: 13 | J17: 20 | K17: 20 | L17: 16 | M17: =SUM(C17:K17) -> 126 | N17: =RANK(M17,$M$6:$M$17) -> 3

Sheet 8s
A1: Hemayetpur Laboratory School and College
A2: 3rd Tutorial Examination Marksheet-2025
A3: Class: Eight
A4: SN | B4: Student’s Name | C4: Subject’s Name & Marks
C5: Bangla-1 | D5: Bangla-2 | E5: English -1 | F5: English -2 | G5: Math. | H5: Science | I5: B.G.S | J5: Agri. | K5: Religion | L5: ICT | M5: Total | N5: Rank
A6: 1 | B6: TANVIN ISLAM | C6: 24 | D6: 26 | E6: 24 | F6: 17 | G6: 24 | H6: 35 | I6: 42 | J6: 30 | K6: 24 | L6: 17 | M6: =SUM(C6:L6) -> 263 | N6: =RANK(M6,$M$6:$M$17) -> 1
A7: 2 | B7: RAJU ISLAM | C7: 24 | D7: 17 | E7: 24 | F7: 17 | G7: 24 | H7: 24 | I7: 35 | J7: 29 | K7: 24 | L7: 17 | M7: 100 | N7: =RANK(M7,$M$6:$M$17) -> 12
A8: 3 | B8: MAINUL ISLAM | C8: 24 | D8: 20 | E8: 24 | F8: 17 | G8: 24 | H8: 24 | I8: 24 | J8: 24 | K8: 24 | L8: 16 | M8: =SUM(C8:L8) -> 221 | N8: =RANK(M8,$M$6:$M$17) -> 5
A9: 4 | B9: MIM AKTER | C9: 24 | D9: 31 | E9: 24 | F9: 17 | G9: 24 | H9: 28 | I9: 40 | J9: 40 | K9: 24 | L9: 10 | M9: =SUM(C9:L9) -> 262 | N9: =RANK(M9,$M$6:$M$17) -> 2
A10: 5 | B10: ALIF HOSSAIN | C10: 24 | D10: 17 | E10: 24 | F10: 17 | G10: 24 | H10: 24 | I10: 24 | J10: 24 | K10: 24 | L10: 14 | M10: =SUM(C10:L10) -> 216 | N10: =RANK(M10,$M$6:$M$17) -> 8
A11: 6 | B11: SIAM AHAMED | C11: 24 | D11: 17 | E11: 24 | F11: 17 | G11: 24 | H11: 24 | I11: 24 | J11: 24 | K11: 24 | L11: 10 | M11: =SUM(C11:L11) -> 212 | N11: =RANK(M11,$M$6:$M$17) -> 10
A12: 7 | B12: SUMIYA AKTER | C12: 24 | D12: 17 | E12: 24 | F12: 17 | G12: 24 | H12: 24 | I12: 26 | J12: 24 | K12: 24 | L12: 10 | M12: =SUM(C12:L12) -> 214 | N12: =RANK(M12,$M$6:$M$17) -> 9
A13: 8 | B13: SAMIHA AKTER | C13: 24 | D13: 17 | E13: 24 | F13: 17 | G13: 24 | H13: 24 | I13: 24 | J13: 24 | K13: 24 | L13: 9 | M13: =SUM(C13:L13) -> 211 | N13: =RANK(M13,$M$6:$M$17) -> 11
A14: 9 | B14: TASMIYA AKTER | C14: 24 | D14: 18 | E14: 24 | F14: 17 | G14: 24 | H14: 24 | I14: 29 | J14: 24 | K14: 24 | L14: 10 | M14: =SUM(C14:L14) -> 218 | N14: =RANK(M14,$M$6:$M$17) -> 6
A15: 10 | B15: SHKIL | C15: 24 | D15: 27 | E15: 24 | F15: 17 | G15: 24 | H15: 24 | I15: 24 | J15: 24 | K15: 24 | L15: 11 | M15: =SUM(C15:L15) -> 223 | N15: =RANK(M15,$M$6:$M$17) -> 4
A16: 11 | B16: RAKIB HASAN | C16: 24 | D16: 17 | E16: 24 | F16: 17 | G16: 24 | H16: 24 | I16: 24 | J16: 24 | K16: 24 | L16: 16 | M16: =SUM(C16:L16) -> 218 | N16: =RANK(M16,$M$6:$M$17) -> 6
A17: 12 | B17: SOUROV ISLAM | C17: 24 | D17: 17 | E17: 24 | F17: 17 | G17: 24 | H17: 28 | I17: 24 | J17: 30 | K17: 24 | L17: 16 | M17: =SUM(C17:L17) -> 228 | N17: =RANK(M17,$M$6:$M$17) -> 3

Sheet 8
A1: SN | B1: Student’s Name | C1: ='8s'!B6 -> TANVIN ISLAM
A2: 1 | B2: Subject’s Name | C2: 3rd Tutorial Exam (30) | D2: 3rd Semester Exam (70) | E2: Total Marks | F2: Grade Letter | G2: Grade Point | H2: G.P.A
B3: Bangla-1 | C3: ='8t'!C6 -> 28 | D3: ='8s'!C6 -> 24 | E3: =SUM(C3:D3) -> 52 | F3: =IF(E3>=80,"A+", IF(E3>=70,"A", IF(E3>=60,"A-", IF(E3>=50,"B", IF(E3>=40,"C", IF(E3>=33,"D","F")))))) -> B | G3: =IF(E3>=80,5, IF(E3>=70,4, IF(E3>=60,3.5, IF(E3>=50,3, IF(E3>=40,2, IF(E3>=33,1,0)))))) -> 3 | H3: =AVERAGE( VALUE(G3), VALUE(G4), VALUE(G5), VALUE(G6), VALUE(G7), VALUE(G8), VALUE(G9), VALUE(G10), VALUE(G11), VALUE(G12)) -> 2.65
B4: Bangla-2 | C4: ='8t'!D6 | D4: ='8s'!D6 -> 26 | E4: =SUM(C4:D4) -> 26 | F4: =IF(E4>=40,"A+", IF(E4>=35,"A", IF(E4>=30,"A-", IF(E4>=25,"B", IF(E4>=20,"C", IF(E4>=16,"D","F")))))) -> B | G4: =IF(E4>=40,5, IF(E4>=35,4, IF(E4>=30,3.5, IF(E4>=25,3, IF(E4>=20,2, IF(E4>=16,1,0)))))) -> 3
B5: English-1 | C5: ='8t'!E6 -> 10 | D5: ='8s'!E6 -> 24 | E5: =SUM(C5:D5) -> 34 | F5: =IF(E5>=80,"A+", IF(E5>=70,"A", IF(E5>=60,"A-", IF(E5>=50,"B", IF(E5>=40,"C", IF(E5>=33,"D","F")))))) -> D | G5: =IF(E5>=80,5, IF(E5>=70,4, IF(E5>=60,3.5, IF(E5>=50,3, IF(E5>=40,2, IF(E5>=33,1,0)))))) -> 1
B6: English-2 | C6: ='8t'!F6 | D6: ='8s'!F6 -> 17 | E6: =SUM(C6:D6) -> 17 | F6: =IF(E6>=40,"A+", IF(E6>=35,"A", IF(E6>=30,"A-", IF(E6>=25,"B", IF(E6>=20,"C", IF(E6>=16,"D","F")))))) -> D | G6: =IF(E6>=40,5, IF(E6>=35,4, IF(E6>=30,3.5, IF(E6>=25,3, IF(E6>=20,2, IF(E6>=16,1,0)))))) -> 1
B7: Mathematics | C7: ='8t'!G6 -> 20 | D7: ='8s'!G6 -> 24 | E7: =SUM(C7:D7) -> 44 | F7: =IF(E7>=80,"A+", IF(E7>=70,"A", IF(E7>=60,"A-", IF(E7>=50,"B", IF(E7>=40,"C", IF(E7>=33,"D","F")))))) -> C | G7: =IF(E7>=80,5, IF(E7>=70,4, IF(E7>=60,3.5, IF(E7>=50,3, IF(E7>=40,2, IF(E7>=33,1,0)))))) -> 2
B8: Science | C8: ='8t'!H6 -> 18 | D8: ='8s'!H6 -> 35 | E8: =SUM(C8:D8) -> 53 | F8: =IF(E8>=80,"A+", IF(E8>=70,"A", IF(E8>=60,"A-", IF(E8>=50,"B", IF(E8>=40,"C", IF(E8>=33,"D","F")))))) -> B | G8: =IF(E8>=80,5, IF(E8>=70,4, IF(E8>=60,3.5, IF(E8>=50,3, IF(E8>=40,2, IF(E8>=33,1,0)))))) -> 3
B9: B.G.S | C9: ='8t'!I6 -> 19 | D9: ='8s'!I6 -> 42 | E9: =SUM(C9:D9) -> 61 | F9: =IF(E9>=80,"A+", IF(E9>=70,"A", IF(E9>=60,"A-", IF(E9>=50,"B", IF(E9>=40,"C", IF(E9>=33,"D","F")))))) -> A- | G9: =IF(E9>=80,5, IF(E9>=70,4, IF(E9>=60,3.5, IF(E9>=50,3, IF(E9>=40,2, IF(E9>=33,1,0)))))) -> 3.5
B10: Agri. | C10: ='8t'!J6 -> 30 | D10: ='8s'!J6 -> 30 | E10: =SUM(C10:D10) -> 60 | F10: =IF(E10>=80,"A+", IF(E10>=70,"A", IF(E10>=60,"A-", IF(E10>=50,"B", IF(E10>=40,"C", IF(E10>=33,"D","F")))))) -> A- | G10: =IF(E10>=80,5, IF(E10>=70,4, IF(E10>=60,3.5, IF(E10>=50,3, IF(E10>=40,2, IF(E10>=33,1,0)))))) -> 3.5
B11: Religion | C11: ='8t'!K6 -> 30 | D11: ='8s'!K6 -> 24 | E11: =SUM(C11:D11) -> 54 | F11: =IF(E11>=80,"A+", IF(E11>=70,"A", IF(E11>=60,"A-", IF(E11>=50,"B", IF(E11>=40,"C", IF(E11>=33,"D","F")))))) -> B | G11: =IF(E11>=80,5, IF(E11>=70,4, IF(E11>=60,3.5, IF(E11>=50,3, IF(E11>=40,2, IF(E11>=33,1,0)))))) -> 3
B12: ICT | C12: ='8t'!L6 -> 17 | D12: ='8s'!L6 -> 17 | E12: =SUM(C12:D12) -> 34 | F12: =IF(E12>=40,"A+", IF(E12>=35,"A", IF(E12>=30,"A-", IF(E12>=25,"B", IF(E12>=20,"C", IF(E12>=16,"D","F")))))) -> A- | G12: =IF(E12>=40,5, IF(E12>=35,4, IF(E12>=30,3.5, IF(E12>=25,3, IF(E12>=20,2, IF(E12>=16,1,0)))))) -> 3.5
A13: SN | B13: Student’s Name | C13: ='8s'!B7 -> RAJU ISLAM
A14: 2 | B14: Subject’s Name | C14: ='8'!C2 -> 3rd Tutorial Exam (30) | D14: ='8'!D2 -> 3rd Semester Exam (70) | E14: Total Marks | F14: Grade Letter | G14: Grade Point | H14: G.P.A
B15: Bangla-1 | C15: ='8t'!C7 -> 25 | D15: ='8s'!C7 -> 24 | E15: =SUM(C15:D15) -> 49 | F15: =IF(E15>=80,"A+", IF(E15>=70,"A", IF(E15>=60,"A-", IF(E15>=50,"B", IF(E15>=40,"C", IF(E15>=33,"D","F")))))) -> C | G15: =IF(E15>=80,5, IF(E15>=70,4, IF(E15>=60,3.5, IF(E15>=50,3, IF(E15>=40,2, IF(E15>=33,1,0)))))) -> 2 | H15: =AVERAGE( VALUE(G15), VALUE(G16), VALUE(G17), VALUE(G18), VALUE(G19), VALUE(G20), VALUE(G21), VALUE(G22), VALUE(G23), VALUE(G24)) -> 1.75
B16: Bangla-2 | C16: ='8t'!D7 | D16: ='8s'!D7 -> 17 | E16: =SUM(C16:D16) -> 17 | F16: =IF(E16>=40,"A+", IF(E16>=35,"A", IF(E16>=30,"A-", IF(E16>=25,"B", IF(E16>=20,"C", IF(E16>=16,"D","F")))))) -> D | G16: =IF(E16>=40,5, IF(E16>=35,4, IF(E16>=30,3.5, IF(E16>=25,3, IF(E16>=20,2, IF(E16>=16,1,0)))))) -> 1
B17: English-1 | C17: ='8t'!E7 -> 10 | D17: ='8s'!E7 -> 24 | E17: =SUM(C17:D17) -> 34 | F17: =IF(E17>=80,"A+", IF(E17>=70,"A", IF(E17>=60,"A-", IF(E17>=50,"B", IF(E17>=40,"C", IF(E17>=33,"D","F")))))) -> D | G17: =IF(E17>=80,5, IF(E17>=70,4, IF(E17>=60,3.5, IF(E17>=50,3, IF(E17>=40,2, IF(E17>=33,1,0)))))) -> 1
B18: English-2 | C18: ='8t'!F7 | D18: ='8s'!F7 -> 17 | E18: =SUM(C18:D18) -> 17 | F18: =IF(E18>=40,"A+", IF(E18>=35,"A", IF(E18>=30,"A-", IF(E18>=25,"B", IF(E18>=20,"C", IF(E18>=16,"D","F")))))) -> D | G18: =IF(E18>=40,5, IF(E18>=35,4, IF(E18>=30,3.5, IF(E18>=25,3, IF(E18>=20,2, IF(E18>=16,1,0)))))) -> 1
B19: Mathematics | C19: ='8t'!G7 -> 10 | D19: ='8s'!G7 -> 24 | E19: =SUM(C19:D19) -> 34 | F19: =IF(E19>=80,"A+", IF(E19>=70,"A", IF(E19>=60,"A-", IF(E19>=50,"B", IF(E19>=40,"C", IF(E19>=33,"D","F")))))) -> D | G19: =IF(E19>=80,5, IF(E19>=70,4, IF(E19>=60,3.5, IF(E19>=50,3, IF(E19>=40,2, IF(E19>=33,1,0)))))) -> 1
B20: Science | C20: ='7t'!H7 -> 28 | D20: ='8s'!H7 -> 24 | E20: =SUM(C20:D20) -> 52 | F20: =IF(E20>=80,"A+", IF(E20>=70,"A", IF(E20>=60,"A-", IF(E20>=50,"B", IF(E20>=40,"C", IF(E20>=33,"D","F")))))) -> B | G20: =IF(E20>=80,5, IF(E20>=70,4, IF(E20>=60,3.5, IF(E20>=50,3, IF(E20>=40,2, IF(E20>=33,1,0)))))) -> 3
B21: B.G.S | C21: ='8t'!I7 | D21: ='8s'!I7 -> 35 | E21: =SUM(C21:D21) -> 35 | F21: =IF(E21>=80,"A+", IF(E21>=70,"A", IF(E21>=60,"A-", IF(E21>=50,"B", IF(E21>=40,"C", IF(E21>=33,"D","F")))))) -> D | G21: =IF(E21>=80,5, IF(E21>=70,4, IF(E21>=60,3.5, IF(E21>=50,3, IF(E21>=40,2, IF(E21>=33,1,0)))))) -> 1
B22: Agri. | C22: ='8t'!J7 -> 20 | D22: ='8s'!J7 -> 29 | E22: =SUM(C22:D22) -> 49 | F22: =IF(E22>=80,"A+", IF(E22>=70,"A", IF(E22>=60,"A-", IF(E22>=50,"B", IF(E22>=40,"C", IF(E22>=33,"D","F")))))) -> C | G22: =IF(E22>=80,5, IF(E22>=70,4, IF(E22>=60,3.5, IF(E22>=50,3, IF(E22>=40,2, IF(E22>=33,1,0)))))) -> 2
B23: Religion | C23: ='8t'!K7 -> 20 | D23: ='8s'!K7 -> 24 | E23: =SUM(C23:D23) -> 44 | F23: =IF(E23>=80,"A+", IF(E23>=70,"A", IF(E23>=60,"A-", IF(E23>=50,"B", IF(E23>=40,"C", IF(E23>=33,"D","F")))))) -> C | G23: =IF(E23>=80,5, IF(E23>=70,4, IF(E23>=60,3.5, IF(E23>=50,3, IF(E23>=40,2, IF(E23>=33,1,0)))))) -> 2
B24: ICT | C24: ='8t'!L7 -> 17 | D24: ='8s'!L7 -> 17 | E24: =SUM(C24:D24) -> 34 | F24: =IF(E24>=40,"A+", IF(E24>=35,"A", IF(E24>=30,"A-", IF(E24>=25,"B", IF(E24>=20,"C", IF(E24>=16,"D","F")))))) -> A- | G24: =IF(E24>=40,5, IF(E24>=35,4, IF(E24>=30,3.5, IF(E24>=25,3, IF(E24>=20,2, IF(E24>=16,1,0)))))) -> 3.5
A25: SN | B25: Student’s Name | C25: ='8s'!B8 -> MAINUL ISLAM
A26: 3 | B26: Subject’s Name | C26: ='8'!C14 -> 3rd Tutorial Exam (30) | D26: ='8'!D14 -> 3rd Semester Exam (70) | E26: Total Marks | F26: Grade Letter | G26: Grade Point | H26: G.P.A
B27: Bangla-1 | C27: ='8t'!C8 -> 15 | D27: ='8s'!C8 -> 24 | E27: =SUM(C27:D27) -> 39 | F27: =IF(E27>=80,"A+", IF(E27>=70,"A", IF(E27>=60,"A-", IF(E27>=50,"B", IF(E27>=40,"C", IF(E27>=33,"D","F")))))) -> D | G27: =IF(E27>=80,5, IF(E27>=70,4, IF(E27>=60,3.5, IF(E27>=50,3, IF(E27>=40,2, IF(E27>=33,1,0)))))) -> 1 | H27: =AVERAGE( VALUE(G27), VALUE(G28), VALUE(G29), VALUE(G30), VALUE(G31), VALUE(G32), VALUE(G33), VALUE(G34), VALUE(G35), VALUE(G36)) -> 1.55
B28: Bangla-2 | C28: ='8t'!D8 | D28: ='8s'!D8 -> 20 | E28: =SUM(C28:D28) -> 20 | F28: =IF(E28>=40,"A+", IF(E28>=35,"A", IF(E28>=30,"A-", IF(E28>=25,"B", IF(E28>=20,"C", IF(E28>=16,"D","F")))))) -> C | G28: =IF(E28>=40,5, IF(E28>=35,4, IF(E28>=30,3.5, IF(E28>=25,3, IF(E28>=20,2, IF(E28>=16,1,0)))))) -> 2
B29: English-1 | C29: ='8t'!E8 -> 11 | D29: ='8s'!E8 -> 24 | E29: =SUM(C29:D29) -> 35 | F29: =IF(E29>=80,"A+", IF(E29>=70,"A", IF(E29>=60,"A-", IF(E29>=50,"B", IF(E29>=40,"C", IF(E29>=33,"D","F")))))) -> D | G29: =IF(E29>=80,5, IF(E29>=70,4, IF(E29>=60,3.5, IF(E29>=50,3, IF(E29>=40,2, IF(E29>=33,1,0)))))) -> 1
